Workbook

Sheet VFF Shoes Stock
A1: VFF Shoe Inventory List (by Store)
A2: As of 09/25/2026 (End of Business Hours)
A3: Code | B3: Model | C3: Color | D3: Size | E3: K Village | G3: Central CL (Department) | I3: Siam Discovery | K3: Paradise Park | M3: Central LP | O3: Total
E4: Quantity | F4: Return | G4: Quantity | H4: Return | I4: Quantity | J4: Return | K4: Quantity | L4: Return | M4: Quantity | N4: Return | O4: Quantity | P4: Return
A5: VFF0002(BK/BL,M40) | B5: VFF V-Run | C5: Black/Blue | D5: M40 | E5: =SUMIFS('K Village'!$D:$D,'K Village'!$B:$B,$A5) -> 0 | G5: =SUMIFS('Central CL (Department)'!$BO:$BO,'Central CL (Department)'!$A:$A,$A5) -> 0 | I5: =SUMIFS('Siam Discovery'!$C:$C,'Siam Discovery'!$A:$A,$A5) -> 0 | K5: =SUMIFS('Paradise Park'!$C:$C,'Paradise Park'!$A:$A,$A5) -> 0 | M5: =SUMIFS('Central LP'!$D:$D,'Central LP'!$B:$B,$A5) -> 1 | O5: =E5+G5+I5+K5+M5 -> 1 | P5: =F5+H5+J5+L5+N5 -> 0
A6: VFF0002(BK/BL,M41) | B6: VFF V-Run | C6: Black/Blue | D6: M41 | E6: =SUMIFS('K Village'!$D:$D,'K Village'!$B:$B,$A6) -> 0 | G6: =SUMIFS('Central CL (Department)'!$BO:$BO,'Central CL (Department)'!$A:$A,$A6) -> 2 | I6: =SUMIFS('Siam Discovery'!$C:$C,'Siam Discovery'!$A:$A,$A6) -> 0 | K6: =SUMIFS('Paradise Park'!$C:$C,'Paradise Park'!$A:$A,$A6) -> 1 | M6: =SUMIFS('Central LP'!$D:$D,'Central LP'!$B:$B,$A6) -> 3 | O6: =E6+G6+I6+K6+M6 -> 6 | P6: =F6+H6+J6+L6+N6 -> 0
A7: VFF0002(BK/BL,M42) | B7: VFF V-Run | C7: Black/Blue | D7: M42 | E7: =SUMIFS('K Village'!$D:$D,'K Village'!$B:$B,$A7) -> 0 | G7: =SUMIFS('Central CL (Department)'!$BO:$BO,'Central CL (Department)'!$A:$A,$A7) -> 3 | I7: =SUMIFS('Siam Discovery'!$C:$C,'Siam Discovery'!$A:$A,$A7) -> 0 | K7: =SUMIFS('Paradise Park'!$C:$C,'Paradise Park'!$A:$A,$A7) -> 1 | M7: =SUMIFS('Central LP'!$D:$D,'Central LP'!$B:$B,$A7) -> 1 | O7: =E7+G7+I7+K7+M7 -> 5 | P7: =F7+H7+J7+L7+N7 -> 0
A8: VFF0002(BK/BL,M43) | B8: VFF V-Run | C8: Black/Blue | D8: M43 | E8: =SUMIFS('K Village'!$D:$D,'K Village'!$B:$B,$A8) -> 0 | G8: =SUMIFS('Central CL (Department)'!$BO:$BO,'Central CL (Department)'!$A:$A,$A8) -> 0 | I8: =SUMIFS('Siam Discovery'!$C:$C,'Siam Discovery'!$A:$A,$A8) -> 2 | K8: =SUMIFS('Paradise Park'!$C:$C,'Paradise Park'!$A:$A,$A8) -> 1 | M8: =SUMIFS('Central LP'!$D:$D,'Central LP'!$B:$B,$A8) -> 2 | O8: =E8+G8+I8+K8+M8 -> 5 | P8: =F8+H8+J8+L8+N8 -> 0
A9: VFF0002(BK/BL,M44) | B9: VFF V-Run | C9: Black/Blue | D9: M44 | E9: =SUMIFS('K Village'!$D:$D,'K Village'!$B:$B,$A9) -> 0 | G9: =SUMIFS('Central CL (Department)'!$BO:$BO,'Central CL (Department)'!$A:$A,$A9) -> 0 | I9: =SUMIFS('Siam Discovery'!$C:$C,'Siam Discovery'!$A:$A,$A9) -> 0 | K9: =SUMIFS('Paradise Park'!$C:$C,'Paradise Park'!$A:$A,$A9) -> 0 | M9: =SUMIFS('Central LP'!$D:$D,'Central LP'!$B:$B,$A9) -> 1 | O9: =E9+G9+I9+K9+M9 -> 1 | P9: =F9+H9+J9+L9+N9 -> 0
A10: VFF0002(BK/BL,M45) | B10: VFF V-Run | C10: Black/Blue | D10: M45 | E10: =SUMIFS('K Village'!$D:$D,'K Village'!$B:$B,$A10) -> 0 | G10: =SUMIFS('Central CL (Department)'!$BO:$BO,'Central CL (Department)'!$A:$A,$A10) -> 1 | I10: =SUMIFS('Siam Discovery'!$C:$C,'Siam Discovery'!$A:$A,$A10) -> 0 | K10: =SUMIFS('Paradise Park'!$C:$C,'Paradise Park'!$A:$A,$A10) -> 2 | M10: =SUMIFS('Central LP'!$D:$D,'Central LP'!$B:$B,$A10) -> 2 | O10: =E10+G10+I10+K10+M10 -> 5 | P10: =F10+H10+J10+L10+N10 -> 0
A11: VFF0002(BK/BL,M46) | B11: VFF V-Run | C11: Black/Blue | D11: M46 | E11: =SUMIFS('K Village'!$D:$D,'K Village'!$B:$B,$A11) -> 0 | G11: =SUMIFS('Central CL (Department)'!$BO:$BO,'Central CL (Department)'!$A:$A,$A11) -> 1 | I11: 0 | K11: =SUMIFS('Paradise Park'!$C:$C,'Paradise Park'!$A:$A,$A11) -> 3 | M11: =SUMIFS('Central LP'!$D:$D,'Central LP'!$B:$B,$A11) -> 1 | O11: =E11+G11+I11+K11+M11 -> 5 | P11: =F11+H11+J11+L11+N11 -> 0
A12: VFF0002(BK/BL,M47) | B12: VFF V-Run | C12: Black/Blue | D12: M47 | E12: =SUMIFS('K Village'!$D:$D,'K Village'!$B:$B,$A12) -> 0 | G12: =SUMIFS('Central CL (Department)'!$BO:$BO,'Central CL (Department)'!$A:$A,$A12) -> 2 | I12: =SUMIFS('Siam Discovery'!$C:$C,'Siam Discovery'!$A:$A,$A12) -> 0 | K12: =SUMIFS('Paradise Park'!$C:$C,'Paradise Park'!$A:$A,$A12) -> 0 | M12: =SUMIFS('Central LP'!$D:$D,'Central LP'!$B:$B,$A12) -> 1 | O12: =E12+G12+I12+K12+M12 -> 3 | P12: =F12+H12+J12+L12+N12 -> 0
A13: VFF0002(BK/BL,M48) | B13: VFF V-Run | C13: Black/Blue | D13: M48 | E13: =SUMIFS('K Village'!$D:$D,'K Village'!$B:$B,$A13) -> 0 | G13: =SUMIFS('Central CL (Department)'!$BO:$BO,'Central CL (Department)'!$A:$A,$A13) -> 0 | I13: =SUMIFS('Siam Discovery'!$C:$C,'Siam Discovery'!$A:$A,$A13) -> 0 | K13: =SUMIFS('Paradise Park'!$C:$C,'Paradise Park'!$A:$A,$A13) -> 1 | M13: =SUMIFS('Central LP'!$D:$D,'Central LP'!$B:$B,$A13) -> 0 | O13: =E13+G13+I13+K13+M13 -> 1 | P13: =F13+H13+J13+L13+N13 -> 0
A14: VFF0002(BK/F,W36) | B14: VFF V-Run | C14: Black/Fig | D14: W36 | E14: =SUMIFS('K Village'!$D:$D,'K Village'!$B:$B,$A14) -> 1 | G14: =SUMIFS('Central CL (Department)'!$BO:$BO,'Central CL (Department)'!$A:$A,$A14) -> 1 | I14: =SUMIFS('Siam Discovery'!$C:$C,'Siam Discovery'!$A:$A,$A14) -> 0 | K14: =SUMIFS('Paradise Park'!$C:$C,'Paradise Park'!$A:$A,$A14) -> 2 | M14: =SUMIFS('Central LP'!$D:$D,'Central LP'!$B:$B,$A14) -> 1 | O14: =E14+G14+I14+K14+M14 -> 5 | P14: =F14+H14+J14+L14+N14 -> 0
A15: VFF0002(BK/F,W37) | B15: VFF V-Run | C15: Black/Fig | D15: W37 | E15: =SUMIFS('K Village'!$D:$D,'K Village'!$B:$B,$A15) -> 2 | G15: =SUMIFS('Central CL (Department)'!$BO:$BO,'Central CL (Department)'!$A:$A,$A15) -> 2 | I15: =SUMIFS('Siam Discovery'!$C:$C,'Siam Discovery'!$A:$A,$A15) -> 0 | K15: =SUMIFS('Paradise Park'!$C:$C,'Paradise Park'!$A:$A,$A15) -> 2 | M15: =SUMIFS('Central LP'!$D:$D,'Central LP'!$B:$B,$A15) -> 1 | O15: =E15+G15+I15+K15+M15 -> 7 | P15: =F15+H15+J15+L15+N15 -> 0
A16: VFF0002(BK/F,W38) | B16: VFF V-Run | C16: Black/Fig | D16: W38 | E16: =SUMIFS('K Village'!$D:$D,'K Village'!$B:$B,$A16) -> 2 | G16: =SUMIFS('Central CL (Department)'!$BO:$BO,'Central CL (Department)'!$A:$A,$A16) -> 1 | I16: =SUMIFS('Siam Discovery'!$C:$C,'Siam Discovery'!$A:$A,$A16) -> 2 | K16: =SUMIFS('Paradise Park'!$C:$C,'Paradise Park'!$A:$A,$A16) -> 3 | M16: =SUMIFS('Central LP'!$D:$D,'Central LP'!$B:$B,$A16) -> 1 | O16: =E16+G16+I16+K16+M16 -> 9 | P16: =F16+H16+J16+L16+N16 -> 0
A17: VFF0002(BK/F,W39) | B17: VFF V-Run | C17: Black/Fig | D17: W39 | E17: =SUMIFS('K Village'!$D:$D,'K Village'!$B:$B,$A17) -> 2 | G17: =SUMIFS('Central CL (Department)'!$BO:$BO,'Central CL (Department)'!$A:$A,$A17) -> 1 | I17: =SUMIFS('Siam Discovery'!$C:$C,'Siam Discovery'!$A:$A,$A17) -> 2 | K17: =SUMIFS('Paradise Park'!$C:$C,'Paradise Park'!$A:$A,$A17) -> 0 | M17: =SUMIFS('Central LP'!$D:$D,'Central LP'!$B:$B,$A17) -> 1 | O17: =E17+G17+I17+K17+M17 -> 6 | P17: =F17+H17+J17+L17+N17 -> 0
A18: VFF0002(BK/F,W40) | B18: VFF V-Run | C18: Black/Fig | D18: W40 | E18: =SUMIFS('K Village'!$D:$D,'K Village'!$B:$B,$A18) -> 2 | G18: =SUMIFS('Central CL (Department)'!$BO:$BO,'Central CL (Department)'!$A:$A,$A18) -> 1 | I18: =SUMIFS('Siam Discovery'!$C:$C,'Siam Discovery'!$A:$A,$A18) -> 1 | K18: =SUMIFS('Paradise Park'!$C:$C,'Paradise Park'!$A:$A,$A18) -> 0 | M18: =SUMIFS('Central LP'!$D:$D,'Central LP'!$B:$B,$A18) -> 1 | O18: =E18+G18+I18+K18+M18 -> 5 | P18: =F18+H18+J18+L18+N18 -> 0
A19: VFF0002(BK/F,W41) | B19: VFF V-Run | C19: Black/Fig | D19: W41 | E19: =SUMIFS('K Village'!$D:$D,'K Village'!$B:$B,$A19) -> 3 | G19: =SUMIFS('Central CL (Department)'!$BO:$BO,'Central CL (Department)'!$A:$A,$A19) -> 1 | I19: =SUMIFS('Siam Discovery'!$C:$C,'Siam Discovery'!$A:$A,$A19) -> 0 | K19: =SUMIFS('Paradise Park'!$C:$C,'Paradise Park'!$A:$A,$A19) -> 2 | M19: =SUMIFS('Central LP'!$D:$D,'Central LP'!$B:$B,$A19) -> 1 | O19: =E19+G19+I19+K19+M19 -> 7 | P19: =F19+H19+J19+L19+N19 -> 0
A20: VFF0002(BK/LI/BK,M38) | B20: VFF V-Run | C20: Black Lime/Black | D20: M38 | E20: =SUMIFS('K Village'!$D:$D,'K Village'!$B:$B,$A20) -> 1 | G20: =SUMIFS('Central CL (Department)'!$BO:$BO,'Central CL (Department)'!$A:$A,$A20) -> 0 | I20: =SUMIFS('Siam Discovery'!$C:$C,'Siam Discovery'!$A:$A,$A20) -> 0 | K20: =SUMIFS('Paradise Park'!$C:$C,'Paradise Park'!$A:$A,$A20) -> 0 | M20: =SUMIFS('Central LP'!$D:$D,'Central LP'!$B:$B,$A20) -> 0 | O20: =E20+G20+I20+K20+M20 -> 1 | P20: =F20+H20+J20+L20+N20 -> 0
A21: VFF0002(BK/LI/BK,M39) | B21: VFF V-Run | C21: Black Lime/Black | D21: M39 | E21: =SUMIFS('K Village'!$D:$D,'K Village'!$B:$B,$A21) -> 1 | G21: =SUMIFS('Central CL (Department)'!$BO:$BO,'Central CL (Department)'!$A:$A,$A21) -> 0 | I21: =SUMIFS('Siam Discovery'!$C:$C,'Siam Discovery'!$A:$A,$A21) -> 0 | K21: =SUMIFS('Paradise Park'!$C:$C,'Paradise Park'!$A:$A,$A21) -> 0 | M21: =SUMIFS('Central LP'!$D:$D,'Central LP'!$B:$B,$A21) -> 0 | O21: =E21+G21+I21+K21+M21 -> 1 | P21: =F21+H21+J21+L21+N21 -> 0
A22: VFF0002(BK/LI/BK,M40) | B22: VFF V-Run | C22: Black Lime/Black | D22: M40 | E22: =SUMIFS('K Village'!$D:$D,'K Village'!$B:$B,$A22) -> 1 | G22: =SUMIFS('Central CL (Department)'!$BO:$BO,'Central CL (Department)'!$A:$A,$A22) -> 0 | I22: =SUMIFS('Siam Discovery'!$C:$C,'Siam Discovery'!$A:$A,$A22) -> 0 | K22: =SUMIFS('Paradise Park'!$C:$C,'Paradise Park'!$A:$A,$A22) -> 2 | M22: =SUMIFS('Central LP'!$D:$D,'Central LP'!$B:$B,$A22) -> 1 | O22: =E22+G22+I22+K22+M22 -> 4 | P22: =F22+H22+J22+L22+N22 -> 0
A23: VFF0002(BK/LI/BK,M41) | B23: VFF V-Run | C23: Black Lime/Black | D23: M41 | E23: =SUMIFS('K Village'!$D:$D,'K Village'!$B:$B,$A23) -> 2 | G23: =SUMIFS('Central CL (Department)'!$BO:$BO,'Central CL (Department)'!$A:$A,$A23) -> 1 | I23: =SUMIFS('Siam Discovery'!$C:$C,'Siam Discovery'!$A:$A,$A23) -> 1 | K23: =SUMIFS('Paradise Park'!$C:$C,'Paradise Park'!$A:$A,$A23) -> 4 | M23: =SUMIFS('Central LP'!$D:$D,'Central LP'!$B:$B,$A23) -> 1 | O23: =E23+G23+I23+K23+M23 -> 9 | P23: =F23+H23+J23+L23+N23 -> 0
... A26: VFF0002(BK/LI/BK,M44) | B26: VFF V-Run | C26: Black Lime/Black | D26: M44 | E26: =SUMIFS('K Village'!$D:$D,'K Village'!$B:$B,$A26) -> 1 | G26: =SUMIFS('Central CL (Department)'!$BO:$BO,'Central CL (Department)'!$A:$A,$A26) -> 2 | I26: =SUMIFS('Siam Discovery'!$C:$C,'Siam Discovery'!$A:$A,$A26) -> 1 | K26: =SUMIFS('Paradise Park'!$C:$C,'Paradise Park'!$A:$A,$A26) -> 2 | M26: =SUMIFS('Central LP'!$D:$D,'Central LP'!$B:$B,$A26) -> 2 | O26: =E26+G26+I26+K26+M26 -> 8 | P26: =F26+H26+J26+L26+N26 -> 0
A27: VFF0002(BK/LI/BK,M45) | B27: VFF V-Run | C27: Black Lime/Black | D27: M45 | E27: =SUMIFS('K Village'!$D:$D,'K Village'!$B:$B,$A27) -> 1 | G27: =SUMIFS('Central CL (Department)'!$BO:$BO,'Central CL (Department)'!$A:$A,$A27) -> 1 | I27: =SUMIFS('Siam Discovery'!$C:$C,'Siam Discovery'!$A:$A,$A27) -> 1 | K27: =SUMIFS('Paradise Park'!$C:$C,'Paradise Park'!$A:$A,$A27) -> 1 | M27: 1 | O27: =E27+G27+I27+K27+M27 -> 5 | P27: =F27+H27+J27+L27+N27 -> 0
A28: VFF0002(BK/LI/BK,M46) | B28: VFF V-Run | C28: Black Lime/Black | D28: M46 | E28: =SUMIFS('K Village'!$D:$D,'K Village'!$B:$B,$A28) -> 1 | G28: =SUMIFS('Central CL (Department)'!$BO:$BO,'Central CL (Department)'!$A:$A,$A28) -> 0 | I28: =SUMIFS('Siam Discovery'!$C:$C,'Siam Discovery'!$A:$A,$A28) -> 0 | K28: =SUMIFS('Paradise Park'!$C:$C,'Paradise Park'!$A:$A,$A28) -> 2 | M28: =SUMIFS('Central LP'!$D:$D,'Central LP'!$B:$B,$A28) -> 1 | O28: =E28+G28+I28+K28+M28 -> 4 | P28: =F28+H28+J28+L28+N28 -> 0
A29: VFF0002(BK/LI/BK,M47) | B29: VFF V-Run | C29: Black Lime/Black | D29: M47 | E29: =SUMIFS('K Village'!$D:$D,'K Village'!$B:$B,$A29) -> 1 | G29: =SUMIFS('Central CL (Department)'!$BO:$BO,'Central CL (Department)'!$A:$A,$A29) -> 0 | I29: =SUMIFS('Siam Discovery'!$C:$C,'Siam Discovery'!$A:$A,$A29) -> 0 | K29: =SUMIFS('Paradise Park'!$C:$C,'Paradise Park'!$A:$A,$A29) -> 2 | M29: =SUMIFS('Central LP'!$D:$D,'Central LP'!$B:$B,$A29) -> 1 | O29: =E29+G29+I29+K29+M29 -> 4 | P29: =F29+H29+J29+L29+N29 -> 0
A30: VFF0002(BK/YL,M42) | B30: VFF V-Run | C30: Black/Yellow | D30: M42 | E30: =SUMIFS('K Village'!$D:$D,'K Village'!$B:$B,$A30) -> 0 | G30: =SUMIFS('Central CL (Department)'!$BO:$BO,'Central CL (Department)'!$A:$A,$A30) -> 0 | I30: =SUMIFS('Siam Discovery'!$C:$C,'Siam Discovery'!$A:$A,$A30) -> 0 | K30: =SUMIFS('Paradise Park'!$C:$C,'Paradise Park'!$A:$A,$A30) -> 0 | M30: =SUMIFS('Central LP'!$D:$D,'Central LP'!$B:$B,$A30) -> 0 | O30: =E30+G30+I30+K30+M30 -> 0 | P30: =F30+H30+J30+L30+N30 -> 0
A31: VFF0002(BK/YL,M43) | B31: VFF V-Run | C31: Black/Yellow | D31: M43 | E31: =SUMIFS('K Village'!$D:$D,'K Village'!$B:$B,$A31) -> 0 | G31: =SUMIFS('Central CL (Department)'!$BO:$BO,'Central CL (Department)'!$A:$A,$A31) -> 0 | I31: =SUMIFS('Siam Discovery'!$C:$C,'Siam Discovery'!$A:$A,$A31) -> 0 | K31: =SUMIFS('Paradise Park'!$C:$C,'Paradise Park'!$A:$A,$A31) -> 0 | M31: =SUMIFS('Central LP'!$D:$D,'Central LP'!$B:$B,$A31) -> 0 | O31: =E31+G31+I31+K31+M31 -> 0 | P31: =F31+H31+J31+L31+N31 -> 0
A32: VFF0002(BK/YL,M44) | B32: VFF V-Run | C32: Black/Yellow | D32: M44 | E32: =SUMIFS('K Village'!$D:$D,'K Village'!$B:$B,$A32) -> 0 | G32: =SUMIFS('Central CL (Department)'!$BO:$BO,'Central CL (Department)'!$A:$A,$A32) -> 0 | I32: =SUMIFS('Siam Discovery'!$C:$C,'Siam Discovery'!$A:$A,$A32) -> 0 | K32: =SUMIFS('Paradise Park'!$C:$C,'Paradise Park'!$A:$A,$A32) -> 0 | M32: =SUMIFS('Central LP'!$D:$D,'Central LP'!$B:$B,$A32) -> 0 | O32: =E32+G32+I32+K32+M32 -> 0 | P32: =F32+H32+J32+L32+N32 -> 0
A33: VFF0002(BK/YL,M45) | B33: VFF V-Run | C33: Black/Yellow | D33: M45 | E33: =SUMIFS('K Village'!$D:$D,'K Village'!$B:$B,$A33) -> 0 | G33: =SUMIFS('Central CL (Department)'!$BO:$BO,'Central CL (Department)'!$A:$A,$A33) -> 0 | I33: =SUMIFS('Siam Discovery'!$C:$C,'Siam Discovery'!$A:$A,$A33) -> 0 | K33: =SUMIFS('Paradise Park'!$C:$C,'Paradise Park'!$A:$A,$A33) -> 0 | M33: =SUMIFS('Central LP'!$D:$D,'Central LP'!$B:$B,$A33) -> 0 | O33: =E33+G33+I33+K33+M33 -> 0 | P33: =F33+H33+J33+L33+N33 -> 0
A34: VFF0002(BK/YL,M46) | B34: VFF V-Run | C34: Black/Yellow | D34: M46 | E34: =SUMIFS('K Village'!$D:$D,'K Village'!$B:$B,$A34) -> 0 | G34: =SUMIFS('Central CL (Department)'!$BO:$BO,'Central CL (Department)'!$A:$A,$A34) -> 0 | I34: =SUMIFS('Siam Discovery'!$C:$C,'Siam Discovery'!$A:$A,$A34) -> 0 | K34: =SUMIFS('Paradise Park'!$C:$C,'Paradise Park'!$A:$A,$A34) -> 0 | M34: =SUMIFS('Central LP'!$D:$D,'Central LP'!$B:$B,$A34) -> 0 | O34: =E34+G34+I34+K34+M34 -> 0 | P34: =F34+H34+J34+L34+N34 -> 0
A35: VFF0002(BK/YL,M47) | B35: VFF V-Run | C35: Black/Yellow | D35: M47 | E35: =SUMIFS('K Village'!$D:$D,'K Village'!$B:$B,$A35) -> 0 | G35: =SUMIFS('Central CL (Department)'!$BO:$BO,'Central CL (Department)'!$A:$A,$A35) -> 0 | I35: =SUMIFS('Siam Discovery'!$C:$C,'Siam Discovery'!$A:$A,$A35) -> 0 | K35: =SUMIFS('Paradise Park'!$C:$C,'Paradise Park'!$A:$A,$A35) -> 0 | M35: =SUMIFS('Central LP'!$D:$D,'Central LP'!$B:$B,$A35) -> 0 | O35: =E35+G35+I35+K35+M35 -> 0 | P35: =F35+H35+J35+L35+N35 -> 0
A36: VFF0002(BR/IV/BK,M39) | B36: VFF V-Run | C36: Brown Ivory/Black | D36: M39 | E36: =SUMIFS('K Village'!$D:$D,'K Village'!$B:$B,$A36) -> 1 | G36: =SUMIFS('Central CL (Department)'!$BO:$BO,'Central CL (Department)'!$A:$A,$A36) -> 0 | I36: =SUMIFS('Siam Discovery'!$C:$C,'Siam Discovery'!$A:$A,$A36) -> 0 | K36: =SUMIFS('Paradise Park'!$C:$C,'Paradise Park'!$A:$A,$A36) -> 0 | M36: =SUMIFS('Central LP'!$D:$D,'Central LP'!$B:$B,$A36) -> 0 | O36: =E36+G36+I36+K36+M36 -> 1 | P36: =F36+H36+J36+L36+N36 -> 0
A37: VFF0002(BR/IV/BK,M40) | B37: VFF V-Run | C37: Brown Ivory/Black | D37: M40 | E37: =SUMIFS('K Village'!$D:$D,'K Village'!$B:$B,$A37) -> 1 | G37: =SUMIFS('Central CL (Department)'!$BO:$BO,'Central CL (Department)'!$A:$A,$A37) -> 0 | I37: =SUMIFS('Siam Discovery'!$C:$C,'Siam Discovery'!$A:$A,$A37) -> 2 | K37: =SUMIFS('Paradise Park'!$C:$C,'Paradise Park'!$A:$A,$A37) -> 0 | M37: =SUMIFS('Central LP'!$D:$D,'Central LP'!$B:$B,$A37) -> 1 | O37: =E37+G37+I37+K37+M37 -> 4 | P37: =F37+H37+J37+L37+N37 -> 0
A38: VFF0002(BR/IV/BK,M41) | B38: VFF V-Run | C38: Brown Ivory/Black | D38: M41 | E38: =SUMIFS('K Village'!$D:$D,'K Village'!$B:$B,$A38) -> 1 | G38: =SUMIFS('Central CL (Department)'!$BO:$BO,'Central CL (Department)'!$A:$A,$A38) -> 0 | I38: =SUMIFS('Siam Discovery'!$C:$C,'Siam Discovery'!$A:$A,$A38) -> 2 | K38: =SUMIFS('Paradise Park'!$C:$C,'Paradise Park'!$A:$A,$A38) -> 4 | M38: =SUMIFS('Central LP'!$D:$D,'Central LP'!$B:$B,$A38) -> 1 | O38: =E38+G38+I38+K38+M38 -> 8 | P38: =F38+H38+J38+L38+N38 -> 0
A39: VFF0002(BR/IV/BK,M42) | B39: VFF V-Run | C39: Brown Ivory/Black | D39: M42 | E39: =SUMIFS('K Village'!$D:$D,'K Village'!$B:$B,$A39) -> 1 | G39: =SUMIFS('Central CL (Department)'!$BO:$BO,'Central CL (Department)'!$A:$A,$A39) -> 0 | I39: =SUMIFS('Siam Discovery'!$C:$C,'Siam Discovery'!$A:$A,$A39) -> 4 | K39: =SUMIFS('Paradise Park'!$C:$C,'Paradise Park'!$A:$A,$A39) -> 4 | M39: =SUMIFS('Central LP'!$D:$D,'Central LP'!$B:$B,$A39) -> 2 | O39: =E39+G39+I39+K39+M39 -> 11 | P39: =F39+H39+J39+L39+N39 -> 0
... A49: VFF0002(DPK,W37) | B49: VFF V-Run | C49: Dusty Pink | D49: W37 | E49: =SUMIFS('K Village'!$D:$D,'K Village'!$B:$B,$A49) -> 0 | G49: =SUMIFS('Central CL (Department)'!$BO:$BO,'Central CL (Department)'!$A:$A,$A49) -> 2 | I49: =SUMIFS('Siam Discovery'!$C:$C,'Siam Discovery'!$A:$A,$A49) -> 1 | K49: =SUMIFS('Paradise Park'!$C:$C,'Paradise Park'!$A:$A,$A49) -> 1 | M49: =SUMIFS('Central LP'!$D:$D,'Central LP'!$B:$B,$A49) -> 1 | O49: =E49+G49+I49+K49+M49 -> 5 | P49: =F49+H49+J49+L49+N49 -> 0
A50: VFF0002(DPK,W38) | B50: VFF V-Run | C50: Dusty Pink | D50: W38 | E50: =SUMIFS('K Village'!$D:$D,'K Village'!$B:$B,$A50) -> 2 | G50: =SUMIFS('Central CL (Department)'!$BO:$BO,'Central CL (Department)'!$A:$A,$A50) -> 1 | I50: 0 | K50: =SUMIFS('Paradise Park'!$C:$C,'Paradise Park'!$A:$A,$A50) -> 5 | M50: =SUMIFS('Central LP'!$D:$D,'Central LP'!$B:$B,$A50) -> 1 | O50: =E50+G50+I50+K50+M50 -> 9 | P50: =F50+H50+J50+L50+N50 -> 0
A51: VFF0002(DPK,W39) | B51: VFF V-Run | C51: Dusty Pink | D51: W39 | E51: =SUMIFS('K Village'!$D:$D,'K Village'!$B:$B,$A51) -> 2 | G51: =SUMIFS('Central CL (Department)'!$BO:$BO,'Central CL (Department)'!$A:$A,$A51) -> 1 | I51: =SUMIFS('Siam Discovery'!$C:$C,'Siam Discovery'!$A:$A,$A51) -> 2 | K51: =SUMIFS('Paradise Park'!$C:$C,'Paradise Park'!$A:$A,$A51) -> 4 | M51: =SUMIFS('Central LP'!$D:$D,'Central LP'!$B:$B,$A51) -> 2 | O51: =E51+G51+I51+K51+M51 -> 11 | P51: =F51+H51+J51+L51+N51 -> 0
...

Sheet K Village
A1: สินค้า - Kvillage
A2: # | B2: Code | C2: items | D2: Balance
A3: 1 | B3: BFJ0001(BK,L) | C3: BFJ Socks(L, Black) | D3: 9
A4: 2 | B4: BFJ0001(BK,M) | C4: BFJ Socks(M, Black) | D4: 15
A5: 3 | B5: BFJ0001(BK,S) | C5: BFJ Socks(S, Black) | D5: 4
A6: 4 | B6: BFJ0001(BL,L) | C6: BFJ Socks(L, Blue) | D6: 5
A7: 5 | B7: BFJ0001(BL,M) | C7: BFJ Socks(M, Blue) | D7: 9
A8: 6 | B8: BFJ0001(BL,S) | C8: BFJ Socks(S, Blue) | D8: 9
A9: 7 | B9: BFJ0001(GY,L) | C9: BFJ Socks(L, Gray) | D9: 12
A10: 8 | B10: BFJ0001(GY,M) | C10: BFJ Socks(M, Gray) | D10: 16
A11: 9 | B11: BFJ0001(GY,S) | C11: BFJ Socks(S, Gray) | D11: 3
A12: 10 | B12: BFJ0001(PK,L) | C12: BFJ Socks(L, Pink) | D12: 4
A13: 11 | B13: BFJ0001(PK,M) | C13: BFJ Socks(M, Pink) | D13: 6
A14: 12 | B14: BFJ0001(PK,S) | C14: BFJ Socks(S, Pink) | D14: 6
... A483: 481 | B483: VFF0030(BK,M47) | C483: VFF Groundsplay(M47, Black) | D483: 1

Sheet Paradise Park
A1: Paradise Park
A2: Code | B2: items | C2: Balance
A3: BFJ0001(BK,M) | B3: BFJ Socks(M, Black) | C3: 3
A4: BFJ0001(BL,L) | B4: BFJ Socks(L, Blue) | C4: 8
A5: BFJ0001(BL,M) | B5: BFJ Socks(M, Blue) | C5: 5
A6: BFJ0001(BL,S) | B6: BFJ Socks(S, Blue) | C6: 1
A7: BFJ0001(GY,L) | B7: BFJ Socks(L, Gray) | C7: 2
A8: BFJ0001(GY,M) | B8: BFJ Socks(M, Gray) | C8: 7
A9: BFJ0001(PK,L) | B9: BFJ Socks(L, Pink) | C9: 1
A10: BFJ0001(PK,M) | B10: BFJ Socks(M, Pink) | C10: 6
A11: BFJ0001(PK,S) | B11: BFJ Socks(S, Pink) | C11: 3
A12: BFJ0001(YL,L) | B12: BFJ Socks(L, Yellow) | C12: 7
A13: BFJ0001(YL,M) | B13: BFJ Socks(M, Yellow) | C13: 7
A14: MTB0001(LM,W23.5) | B14: Marugo TabiRela(W23.5, Lemon) | C14: 2
... A463: VFF0030(BK,M47) | B463: VFF Groundsplay(M47, Black) | C463: 1
A465: Exported by | B465: acc.bftcoltd@gmail.com
A466: Date Time | B466: 22/9/2026 14:28+07:00

Sheet Siam Discovery
A1: Siam Discovery
A2: Code | B2: items | C2: Balance
A3: BFJ0001(BK,L) | B3: BFJ Socks(L, Black) | C3: 11
A4: BFJ0001(BK,M) | B4: BFJ Socks(M, Black) | C4: 22
A5: BFJ0001(BL,L) | B5: BFJ Socks(L, Blue) | C5: 4
A6: BFJ0001(BL,M) | B6: BFJ Socks(M, Blue) | C6: 11
A7: BFJ0001(BL,S) | B7: BFJ Socks(S, Blue) | C7: 5
A8: BFJ0001(GY,L) | B8: BFJ Socks(L, Gray) | C8: 11
A9: BFJ0001(GY,M) | B9: BFJ Socks(M, Gray) | C9: 23
A10: BFJ0001(GY,S) | B10: BFJ Socks(S, Gray) | C10: 0
A11: BFJ0001(PK,M) | B11: BFJ Socks(M, Pink) | C11: 3
A12: BFJ0001(PK,S) | B12: BFJ Socks(S, Pink) | C12: 5
A13: BFJ0001(YL,L) | B13: BFJ Socks(L, Yellow) | C13: 4
A14: BFJ0001(YL,M) | B14: BFJ Socks(M, Yellow) | C14: 10
... A222: VFF0030(BK,M44) | B222: VFF Groundsplay(M44, Black) | C222: 2
C223: =SUM(C3:C222) -> 627

Sheet Central CL (Department)
A1: Central Chidlom
A2: Code | B2: items | C2: Delivery note | AU2: Total | AV2: Sale | BO2: Balance | BP2: KV, LP, Paradise = 21/9/26
C3: IVT-20250900009 | D3: IVT-20250900011 | E3: CNT-20250900006 | F3: CNT-20250900007 | G3: IVT-20251000002 | H3: IVT-20251000003 | I3: IVT-20251000005 | J3: IVT-20251000009 | K3: IVT-20251000011 | L3: IVT-20251000012 | M3: IVT-20251000013 | N3: CNT-20251000004 | O3: IVT-20251100004 | P3: IVT-20251200006 | Q3: IVT-20251200013 | R3: IVT-20251200017 | S3: IVT-20251200022 | T3: CNT-20251200005 | U3: IVT-20260200002 | V3: IVT-20260200010 | W3: IVT-20260200011 | X3: IVT-20260300001 | Y3: IVT-20260300003 | Z3: IVT-20260300007 | AA3: IVT-20260300010 | AB3: IVT-20260400003 | AC3: IVT-20260400004 | AD3: IVT-20260400008 | AE3: IVT-20260500001 | AF3: IVT-20260500005 | AG3: IVT-20260500012 | AH3: IVT-20260600002 | AI3: IVT-20260600006 | AJ3: IVT-20260600011 | AK3: IVT-20260700005 | AL3: IVT-20260700012 | AM3: CN 21/7/26 | AN3: IVT-20260800003 | AO3: IVT-20260800004 | AP3: IVT-20260800007 | AQ3: IVT-20260800010 | AR3: IVT-20260900007 | AS3: ADJ 24/9/26 在庫0 | AT3: ADD 24/9/26 | AV3: 2025 | AW3: 01/26 | AX3: 02/26 | AY3: 03/26 | AZ3: 04/26 | BA3: 05/26 | BB3: 06/26 | BC3: 07/26 | BD3: 08/26 | BE3: 09/26 | BN3: Total | BP3: CL, Siam dis = 15/9/26
A4: VFF0002(BK/BL,M40) | B4: VFF V-Run(M40, Black/Blue) | C4: 1 | D4: 2 | F4: -1 | I4: 2 | AU4: =SUM(C4:AT4) -> 4 | AV4: 4 | BN4: =SUM(AV4:BM4) -> 4 | BO4: =IF(+AU4-BN4<0,"",+AU4-BN4) -> 0
A5: VFF0002(BK/BL,M41) | B5: VFF V-Run(M41, Black/Blue) | C5: 2 | G5: 1 | I5: 1 | K5: 2 | O5: 1 | AU5: =SUM(C5:AT5) -> 7 | AV5: 1 | BC5: 1 | BD5: 3 | BN5: =SUM(AV5:BM5) -> 5 | BO5: =IF(+AU5-BN5<0,"",+AU5-BN5) -> 2
A6: VFF0002(BK/BL,M42) | B6: VFF V-Run(M42, Black/Blue) | C6: 2 | H6: 1 | I6: 3 | N6: -1 | O6: 1 | AU6: =SUM(C6:AT6) -> 6 | AV6: 2 | AW6: 1 | BN6: =SUM(AV6:BM6) -> 3 | BO6: =IF(+AU6-BN6<0,"",+AU6-BN6) -> 3
A7: VFF0002(BK/BL,M43) | B7: VFF V-Run(M43, Black/Blue) | C7: 2 | H7: 1 | I7: 1 | O7: 1 | U7: 1 | AU7: =SUM(C7:AT7) -> 6 | AV7: 1 | AW7: 2 | AX7: 1 | BC7: 1 | BD7: 1 | BN7: =SUM(AV7:BM7) -> 6 | BO7: =IF(+AU7-BN7<0,"",+AU7-BN7) -> 0
A8: VFF0002(BK/BL,M44) | B8: VFF V-Run(M44, Black/Blue) | C8: 2 | G8: 1 | I8: 1 | AU8: =SUM(C8:AT8) -> 4 | AV8: 1 | AW8: 1 | AX8: 1 | BB8: 1 | BN8: =SUM(AV8:BM8) -> 4 | BO8: =IF(+AU8-BN8<0,"",+AU8-BN8) -> 0
A9: VFF0002(BK/BL,M45) | B9: VFF V-Run(M45, Black/Blue) | C9: 1 | S9: 1 | AU9: =SUM(C9:AT9) -> 2 | AV9: 1 | BN9: =SUM(AV9:BM9) -> 1 | BO9: =IF(+AU9-BN9<0,"",+AU9-BN9) -> 1
A10: VFF0002(BK/BL,M46) | B10: VFF V-Run(M46, Black/Blue) | C10: 1 | H10: 1 | K10: 1 | AU10: =SUM(C10:AT10) -> 3 | AV10: 1 | AY10: 1 | BN10: =SUM(AV10:BM10) -> 2 | BO10: =IF(+AU10-BN10<0,"",+AU10-BN10) -> 1
A11: VFF0002(BK/BL,M47) | B11: VFF V-Run(M47, Black/Blue) | C11: 1 | G11: 1 | K11: 1 | AU11: =SUM(C11:AT11) -> 3 | BD11: 1 | BN11: =SUM(AV11:BM11) -> 1 | BO11: =IF(+AU11-BN11<0,"",+AU11-BN11) -> 2
A12: VFF0002(BK/YL,M42) | B12: VFF V-Run(M42, Black/Yellow) | C12: 1 | I12: 2 | AU12: =SUM(C12:AT12) -> 3 | AV12: 2 | BD12: 1 | BN12: =SUM(AV12:BM12) -> 3 | BO12: =IF(+AU12-BN12<0,"",+AU12-BN12) -> 0
A13: VFF0002(BK/YL,M43) | B13: VFF V-Run(M43, Black/Yellow) | C13: 1 | I13: 2 | AU13: =SUM(C13:AT13) -> 3 | AV13: 1 | AX13: 1 | BA13: 1 | BN13: =SUM(AV13:BM13) -> 3 | BO13: =IF(+AU13-BN13<0,"",+AU13-BN13) -> 0
A14: VFF0002(BK/YL,M44) | B14: VFF V-Run(M44, Black/Yellow) | C14: 1 | AU14: =SUM(C14:AT14) -> 1 | AV14: 1 | BN14: =SUM(AV14:BM14) -> 1 | BO14: =IF(+AU14-BN14<0,"",+AU14-BN14) -> 0
A15: VFF0002(BK/YL,M45) | B15: VFF V-Run(M45, Black/Yellow) | C15: 1 | AU15: =SUM(C15:AT15) -> 1 | AV15: 1 | BN15: =SUM(AV15:BM15) -> 1 | BO15: =IF(+AU15-BN15<0,"",+AU15-BN15) -> 0
A16: VFF0002(BK/YL,M46) | B16: VFF V-Run(M46, Black/Yellow) | C16: 1 | AU16: =SUM(C16:AT16) -> 1 | AY16: 1 | BN16: =SUM(AV16:BM16) -> 1 | BO16: =IF(+AU16-BN16<0,"",+AU16-BN16) -> 0
A17: VFF0002(BK/YL,M47) | B17: VFF V-Run(M47, Black/Yellow) | C17: 1 | AS17: -1 | AU17: =SUM(C17:AT17) -> 0 | BN17: =SUM(AV17:BM17) -> 0 | BO17: =IF(+AU17-BN17<0,"",+AU17-BN17) -> 0
A18: VFF0002(BK/LI/BK,M41) | B18: VFF V-Run(M41, Black Lime/Black) | AH18: 1 | AK18: 1 | AU18: =SUM(C18:AT18) -> 2 | BB18: 1 | BN18: =SUM(AV18:BM18) -> 1 | BO18: =IF(+AU18-BN18<0,"",+AU18-BN18) -> 1
A19: VFF0002(BK/LI/BK,M42) | B19: VFF V-Run(M42, Black Lime/Black) | AH19: 2 | AU19: =SUM(C19:AT19) -> 2 | BD19: 1 | BN19: =SUM(AV19:BM19) -> 1 | BO19: =IF(+AU19-BN19<0,"",+AU19-BN19) -> 1
A20: VFF0002(BK/LI/BK,M43) | B20: VFF V-Run(M43, Black Lime/Black) | AH20: 2 | AL20: 1 | AQ20: 2 | AU20: =SUM(C20:AT20) -> 5 | BC20: 1 | BD20: 2 | BN20: =SUM(AV20:BM20) -> 3 | BO20: =IF(+AU20-BN20<0,"",+AU20-BN20) -> 2
A21: VFF0002(BK/LI/BK,M44) | B21: VFF V-Run(M44, Black Lime/Black) | AH21: 2 | AU21: =SUM(C21:AT21) -> 2 | BN21: =SUM(AV21:BM21) -> 0 | BO21: =IF(+AU21-BN21<0,"",+AU21-BN21) -> 2
A22: VFF0002(BK/LI/BK,M45) | B22: VFF V-Run(M45, Black Lime/Black) | AH22: 1 | AU22: =SUM(C22:AT22) -> 1 | BN22: =SUM(AV22:BM22) -> 0 | BO22: =IF(+AU22-BN22<0,"",+AU22-BN22) -> 1
A23: VFF0002(TT/BK,M40) | B23: VFF V-Run(M40, Total Black) | Q23: 1 | S23: 1 | AU23: =SUM(C23:AT23) -> 2 | AV23: 1 | AW23: 1 | BN23: =SUM(AV23:BM23) -> 2 | BO23: =IF(+AU23-BN23<0,"",+AU23-BN23) -> 0
A24: VFF0002(TT/BK,M41) | B24: VFF V-Run(M41, Total Black) | Q24: 1 | S24: 1 | AC24: 1 | AE24: 1 | AU24: =SUM(C24:AT24) -> 4 | AW24: 1 | AZ24: 2 | BB24: 1 | BN24: =SUM(AV24:BM24) -> 4 | BO24: =IF(+AU24-BN24<0,"",+AU24-BN24) -> 0
A25: VFF0002(TT/BK,M42) | B25: VFF V-Run(M42, Total Black) | Q25: 1 | S25: 1 | W25: 1 | AC25: 1 | AE25: 1 | AU25: =SUM(C25:AT25) -> 5 | AX25: 1 | AZ25: 1 | BN25: =SUM(AV25:BM25) -> 2 | BO25: =IF(+AU25-BN25<0,"",+AU25-BN25) -> 3
A26: VFF0002(TT/BK,M43) | B26: VFF V-Run(M43, Total Black) | Q26: 1 | U26: 1 | X26: 1 | AE26: 1 | AU26: =SUM(C26:AT26) -> 4 | AW26: 1 | BB26: 1 | BD26: 2 | BN26: =SUM(AV26:BM26) -> 4 | BO26: =IF(+AU26-BN26<0,"",+AU26-BN26) -> 0
A27: VFF0002(TT/BK,M44) | B27: VFF V-Run(M44, Total Black) | Q27: 1 | X27: 1 | AE27: 1 | AU27: =SUM(C27:AT27) -> 3 | BA27: 1 | BC27: 1 | BD27: 1 | BN27: =SUM(AV27:BM27) -> 3 | BO27: =IF(+AU27-BN27<0,"",+AU27-BN27) -> 0
A28: VFF0002(TT/BK,M45) | B28: VFF V-Run(M45, Total Black) | Q28: 1 | S28: 1 | AU28: =SUM(C28:AT28) -> 2 | AV28: 1 | AX28: 1 | BN28: =SUM(AV28:BM28) -> 2 | BO28: =IF(+AU28-BN28<0,"",+AU28-BN28) -> 0
A29: VFF0002(BK/F,W36) | B29: VFF V-Run(W36, Black/Fig) | AK29: 1 | AR29: 1 | AU29: =SUM(C29:AT29) -> 2 | BD29: 1 | BN29: =SUM(AV29:BM29) -> 1 | BO29: =IF(+AU29-BN29<0,"",+AU29-BN29) -> 1
A30: VFF0002(BK/F,W37) | B30: VFF V-Run(W37, Black/Fig) | Q30: 1 | Z30: 1 | AJ30: 1 | AN30: 1 | AP30: 1 | AT30: 1 | AU30: =SUM(C30:AT30) -> 6 | AV30: 1 | BA30: 1 | BD30: 1 | BE30: 1 | BN30: =SUM(AV30:BM30) -> 4 | BO30: =IF(+AU30-BN30<0,"",+AU30-BN30) -> 2
A31: VFF0002(BK/F,W38) | B31: VFF V-Run(W38, Black/Fig) | Q31: 1 | S31: 1 | Z31: 2 | AJ31: 1 | AL31: 1 | AP31: 1 | AU31: =SUM(C31:AT31) -> 7 | AW31: 1 | AX31: 1 | BA31: 1 | BB31: 1 | BC31: 1 | BD31: 1 | BN31: =SUM(AV31:BM31) -> 6 | BO31: =IF(+AU31-BN31<0,"",+AU31-BN31) -> 1
A32: VFF0002(BK/F,W39) | B32: VFF V-Run(W39, Black/Fig) | Q32: 1 | U32: 1 | Z32: 2 | AJ32: 1 | AU32: =SUM(C32:AT32) -> 5 | AW32: 1 | AZ32: 1 | BC32: 2 | BN32: =SUM(AV32:BM32) -> 4 | BO32: =IF(+AU32-BN32<0,"",+AU32-BN32) -> 1
A33: VFF0002(BK/F,W40) | B33: VFF V-Run(W40, Black/Fig) | Q33: 1 | Z33: 1 | AJ33: 1 | AU33: =SUM(C33:AT33) -> 3 | BB33: 1 | BD33: 1 | BN33: =SUM(AV33:BM33) -> 2 | BO33: =IF(+AU33-BN33<0,"",+AU33-BN33) -> 1
A34: VFF0002(BK/F,W41) | B34: VFF V-Run(W41, Black/Fig) | Z34: 1 | AL34: 1 | AN34: 1 | AP34: 1 | AU34: =SUM(C34:AT34) -> 4 | BB34: 1 | BD34: 2 | BN34: =SUM(AV34:BM34) -> 3 | BO34: =IF(+AU34-BN34<0,"",+AU34-BN34) -> 1
A35: VFF0002(DL/IV,W37) | B35: VFF V-Run(W37, Deep Lake/Ivory) | C35: 1 | AU35: =SUM(C35:AT35) -> 1 | AV35: 1 | BN35: =SUM(AV35:BM35) -> 1 | BO35: =IF(+AU35-BN35<0,"",+AU35-BN35) -> 0
A36: VFF0002(DL/IV,W38) | B36: VFF V-Run(W38, Deep Lake/Ivory) | C36: 1 | H36: 1 | I36: 1 | N36: -1 | AU36: =SUM(C36:AT36) -> 2 | AV36: 2 | BN36: =SUM(AV36:BM36) -> 2 | BO36: =IF(+AU36-BN36<0,"",+AU36-BN36) -> 0
A37: VFF0002(DL/IV,W39) | B37: VFF V-Run(W39, Deep Lake/Ivory) | C37: 1 | D37: 1 | G37: 1 | H37: 1 | I37: 1 | N37: -1 | AU37: =SUM(C37:AT37) -> 4 | AV37: 4 | BN37: =SUM(AV37:BM37) -> 4 | BO37: =IF(+AU37-BN37<0,"",+AU37-BN37) -> 0
A38: VFF0002(DL/IV,W40) | B38: VFF V-Run(W40, Deep Lake/Ivory) | C38: 1 | D38: 1 | G38: 1 | I38: 1 | R38: 1 | AS38: -1 | AU38: =SUM(C38:AT38) -> 4 | AV38: 4 | BN38: =SUM(AV38:BM38) -> 4 | BO38: =IF(+AU38-BN38<0,"",+AU38-BN38) -> 0
A39: VFF0002(LI/BL,W37) | B39: VFF V-Run(W37, Lime/Blue) | C39: 1 | AU39: =SUM(C39:AT39) -> 1 | AV39: 1 | BN39: =SUM(AV39:BM39) -> 1 | BO39: =IF(+AU39-BN39<0,"",+AU39-BN39) -> 0
A40: VFF0002(LI/BL,W38) | B40: VFF V-Run(W38, Lime/Blue) | C40: 1 | G40: 1 | AU40: =SUM(C40:AT40) -> 2 | AV40: 2 | BN40: =SUM(AV40:BM40) -> 2 | BO40: =IF(+AU40-BN40<0,"",+AU40-BN40) -> 0
...

Sheet Central LP
A1: สินค้า - Coollabo Cen LP 3F
A2: # | B2: Code | C2: items | D2: Balance
A3: 1 | B3: BFJ0001(BK,L) | C3: BFJ Socks(L, Black) | D3: 4
A4: 2 | B4: BFJ0001(BK,M) | C4: BFJ Socks(M, Black) | D4: 1
A5: 3 | B5: BFJ0001(BK,S) | C5: BFJ Socks(S, Black) | D5: 2
A6: 4 | B6: BFJ0001(BL,L) | C6: BFJ Socks(L, Blue) | D6: 6
A7: 5 | B7: BFJ0001(BL,M) | C7: BFJ Socks(M, Blue) | D7: 3
A8: 6 | B8: BFJ0001(BL,S) | C8: BFJ Socks(S, Blue) | D8: 4
A9: 7 | B9: BFJ0001(GY,L) | C9: BFJ Socks(L, Gray) | D9: 10
A10: 8 | B10: BFJ0001(GY,M) | C10: BFJ Socks(M, Gray) | D10: 4
A11: 9 | B11: BFJ0001(GY,S) | C11: BFJ Socks(S, Gray) | D11: 8
A12: 10 | B12: BFJ0001(PK,L) | C12: BFJ Socks(L, Pink) | D12: 9
A13: 11 | B13: BFJ0001(PK,M) | C13: BFJ Socks(M, Pink) | D13: 5
A14: 12 | B14: BFJ0001(PK,S) | C14: BFJ Socks(S, Pink) | D14: 6
... A391: 389 | B391: VFF0030(BK,M45) | C391: VFF Groundsplay(M45, Black) | D391: 1
