Workbook

Sheet 設定
A1: 新入荷商品 店舗配分モデル — 設定シート
A2: 黄色セル（青字）が入力項目です。ここを変えると「配分表」「サマリー」が自動で再計算されます。
A4: 1. モデル別 初回投入率（残りは倉庫保留 → 初速を見て追加配分）
A5: モデル | B5: 初回投入率 | C5: 参考にした既存モデル | D5: 実効の店舗投入率（結果）
A6: VFF Spidrwalk | B6: 0.26 | C6: VFF Spidrwalk（既存カラーの店舗別実績） | D6: =SUMIFS(サマリー!$I$4:$I$8,サマリー!$A$4:$A$8,A6)/SUMIFS(サマリー!$C$4:$C$8,サマリー!$A$4:$A$8,A6) -> 0.30555556
A7: VFF Trailope WP | B7: 0.28 | C7: VFF Trailope ＋ VFF Scramkey | D7: =SUMIFS(サマリー!$I$4:$I$8,サマリー!$A$4:$A$8,A7)/SUMIFS(サマリー!$C$4:$C$8,サマリー!$A$4:$A$8,A7) -> 0.28787879
A8: VFF Groundsplay LS | B8: 0.33 | C8: VFF Groundsplay ＋ VFF Graspifier ＋ VFF Kso Evo（M/W別） | D8: =SUMIFS(サマリー!$I$4:$I$8,サマリー!$A$4:$A$8,A8)/SUMIFS(サマリー!$C$4:$C$8,サマリー!$A$4:$A$8,A8) -> 0.23913043
A10: 2. 店舗別 実績月数（月平均化のため。Paradise Parkは2026年4月開店のため5ヶ月）
A11: 店舗 | B11: 実績月数
A12: K Village | B12: 8
A13: Central Chidlom | B13: 8
A14: Siam Discovery | B14: 8
A15: Paradise Park | B15: 5
A16: Central Lardprao (Dept.) | B16: 8
A18: 3. 店舗別 最低配分足数と1SKUあたり上限（比率に関わらず各店に置く最低数と、1SKUに置く最大数）
A19: 店舗 | B19: 主要 | C19: 端 | D19: 極端 | E19: 1SKU上限
A20: K Village | B20: 2 | C20: 1 | D20: 1 | E20: 2
A21: Central Chidlom | B21: 1 | C21: 1 | D21: 0 | E21: 2
A22: Siam Discovery | B22: 1 | C22: 1 | D22: 0 | E22: 2
A23: Paradise Park | B23: 1 | C23: 0 | D23: 0 | E23: 2
A24: Central Lardprao (Dept.) | B24: 0 | C24: 0 | D24: 0 | E24: 1
A25: サイズ区分の定義（配分表のE列で個別に変更可）：主要＝M41〜44／W38〜40、端＝M40・45・46／W37・41、極端＝M39・47／W36・42
A27: 4. 店舗別 在庫調整係数（既存在庫が過剰な店は1未満にして配分を絞る。係数はシェアの正規化に使うため、減らした分は他店に回る。ただし1SKU上限・最低配分・手動調整が優先されるため、店舗合計は投入率どおりにはならない＝実効率は1.のD列を参照）
A28: 店舗 | B28: 調整係数 | C28: 根拠（9/25時点の既存在庫月数）
A29: K Village | B29: 1 | C29: 約3ヶ月（推定）→ そのまま
A30: Central Chidlom | B30: 1 | C30: 4.5ヶ月 → そのまま
A31: Siam Discovery | B31: 1 | C31: 5.4ヶ月 → そのまま
A32: Paradise Park | B32: 1 | C32: 11ヶ月だが販売は他2店と同水準のため係数は下げず、上限2足で抑える
A33: Central Lardprao (Dept.) | B33: 1.6 | C33: ="30ヶ月。最低配分0・上限1足とし、係数は「入荷の多い主要SKUだけ1足が立つ」水準に調整（合計約"&配分表!N60&"足。配分されないモデル・サイズがあってよい）" -> 30ヶ月。最低配分0・上限1足とし、係数は「入荷の多い主要SKUだけ1足が立つ」水準に調整（合計約7足。配分されないモデル・サイズがあってよい）
A35: 5. 丸め単位（1＝1足単位、3＝3足箱単位）
A36: 丸め単位 | B36: 1
A38: 6. 性別区分の判定（実績データにM/W表記がないため、サイズ39以下をW、40以上をMとみなして集計）
A39: ※ 実績側の40〜42はレディースも含まれ得るため、Groundsplay LS W40〜42の配分はメンズ側の店舗比率に寄ります。必要なら「実績」シートの性別列を手修正してください。
A41: 7. 上限：①店舗投入率（モデル×カラー別の店舗合計÷入荷数）の上限、②初回投入率（上の1.／配分表G列）の上限。①超過はサマリーL列で警告、②は1.の入力で制限（超えると入力エラー）・配分表G列で赤表示。※①は現行の配分実数（Spidrwalk 30.6%）に合わせて31%に設定
A42: 店舗投入率の上限 | B42: 0.31
A43: 初回投入率（配分表G列）の上限 | B43: 0.33

Sheet 実績
A1: 参考モデルの店舗別販売実績（2026年1〜8月、輸出・対EDV卸・オンライン・イベント除く）
A2: 出典：店舗別モデルサイズ別販売足数ピボット_2026年1-8月.xlsx（RawData）。性別はサイズから推定（39以下=W、40以上=M）。
F3: 配分グループ別 店舗シェア（月平均販売足数ベース）
A4: 店舗 | B4: モデル | C4: 性別(推定) | D4: 販売足数 | F4: 配分グループ | G4: 参考モデル | H4: K Village 月平均 | I4: Central CL (Chidlom) 月平均 | J4: Siam Discovery 月平均 | K4: Paradise Park 月平均 | L4: Central LP (Lardprao) 月平均 | M4: 合計 | N4: K Village シェア | O4: Central CL (Chidlom) シェア | P4: Siam Discovery シェア | Q4: Paradise Park シェア | R4: Central LP (Lardprao) シェア | S4: シェア×調整係数 の合計（正規化用）
A5: K Village | B5: VFF Spidrwalk | C5: M | D5: 30 | F5: Spidrwalk | G5: Spidrwalk | H5: =(SUMIFS(実績!$D$5:$D$64,実績!$A$5:$A$64,"K Village",実績!$B$5:$B$64,"VFF Spidrwalk",実績!$C$5:$C$64,"M")+SUMIFS(実績!$D$5:$D$64,実績!$A$5:$A$64,"K Village",実績!$B$5:$B$64,"VFF Spidrwalk",実績!$C$5:$C$64,"W"))/INDEX(設定!$B$12:$B$16,MATCH("K Village",設定!$A$12:$A$16,0)) -> 5 | I5: =(SUMIFS(実績!$D$5:$D$64,実績!$A$5:$A$64,"Central Chidlom",実績!$B$5:$B$64,"VFF Spidrwalk",実績!$C$5:$C$64,"M")+SUMIFS(実績!$D$5:$D$64,実績!$A$5:$A$64,"Central Chidlom",実績!$B$5:$B$64,"VFF Spidrwalk",実績!$C$5:$C$64,"W"))/INDEX(設定!$B$12:$B$16,MATCH("Central Chidlom",設定!$A$12:$A$16,0)) -> 3.25 | J5: =(SUMIFS(実績!$D$5:$D$64,実績!$A$5:$A$64,"Siam Discovery",実績!$B$5:$B$64,"VFF Spidrwalk",実績!$C$5:$C$64,"M")+SUMIFS(実績!$D$5:$D$64,実績!$A$5:$A$64,"Siam Discovery",実績!$B$5:$B$64,"VFF Spidrwalk",実績!$C$5:$C$64,"W"))/INDEX(設定!$B$12:$B$16,MATCH("Siam Discovery",設定!$A$12:$A$16,0)) -> 2.25 | K5: =(SUMIFS(実績!$D$5:$D$64,実績!$A$5:$A$64,"Paradise Park",実績!$B$5:$B$64,"VFF Spidrwalk",実績!$C$5:$C$64,"M")+SUMIFS(実績!$D$5:$D$64,実績!$A$5:$A$64,"Paradise Park",実績!$B$5:$B$64,"VFF Spidrwalk",実績!$C$5:$C$64,"W"))/INDEX(設定!$B$12:$B$16,MATCH("Paradise Park",設定!$A$12:$A$16,0)) -> 0.8 | L5: =(SUMIFS(実績!$D$5:$D$64,実績!$A$5:$A$64,"Central Lardprao (Dept.)",実績!$B$5:$B$64,"VFF Spidrwalk",実績!$C$5:$C$64,"M")+SUMIFS(実績!$D$5:$D$64,実績!$A$5:$A$64,"Central Lardprao (Dept.)",実績!$B$5:$B$64,"VFF Spidrwalk",実績!$C$5:$C$64,"W"))/INDEX(設定!$B$12:$B$16,MATCH("Central Lardprao (Dept.)",設定!$A$12:$A$16,0)) -> 0.5 | M5: =SUM(H5:L5) -> 11.8 | N5: =IF($M5=0,0,H5/$M5) -> 0.42372881 | O5: =IF($M5=0,0,I5/$M5) -> 0.27542373 | P5: =IF($M5=0,0,J5/$M5) -> 0.19067797 | Q5: =IF($M5=0,0,K5/$M5) -> 0.06779661 | R5: =IF($M5=0,0,L5/$M5) -> 0.042372881 | S5: =N5*INDEX(設定!$B$29:$B$33,1)+O5*INDEX(設定!$B$29:$B$33,2)+P5*INDEX(設定!$B$29:$B$33,3)+Q5*INDEX(設定!$B$29:$B$33,4)+R5*INDEX(設定!$B$29:$B$33,5) -> 1.0254237
A6: K Village | B6: VFF Spidrwalk | C6: W | D6: 10 | F6: TrailopeWP | G6: Trailope + Scramkey | H6: =(SUMIFS(実績!$D$5:$D$64,実績!$A$5:$A$64,"K Village",実績!$B$5:$B$64,"VFF Trailope",実績!$C$5:$C$64,"M")+SUMIFS(実績!$D$5:$D$64,実績!$A$5:$A$64,"K Village",実績!$B$5:$B$64,"VFF Trailope",実績!$C$5:$C$64,"W")+SUMIFS(実績!$D$5:$D$64,実績!$A$5:$A$64,"K Village",実績!$B$5:$B$64,"VFF Scramkey",実績!$C$5:$C$64,"M")+SUMIFS(実績!$D$5:$D$64,実績!$A$5:$A$64,"K Village",実績!$B$5:$B$64,"VFF Scramkey",実績!$C$5:$C$64,"W"))/INDEX(設定!$B$12:$B$16,MATCH("K Village",設定!$A$12:$A$16,0)) -> 3.5 | I6: =(SUMIFS(実績!$D$5:$D$64,実績!$A$5:$A$64,"Central Chidlom",実績!$B$5:$B$64,"VFF Trailope",実績!$C$5:$C$64,"M")+SUMIFS(実績!$D$5:$D$64,実績!$A$5:$A$64,"Central Chidlom",実績!$B$5:$B$64,"VFF Trailope",実績!$C$5:$C$64,"W")+SUMIFS(実績!$D$5:$D$64,実績!$A$5:$A$64,"Central Chidlom",実績!$B$5:$B$64,"VFF Scramkey",実績!$C$5:$C$64,"M")+SUMIFS(実績!$D$5:$D$64,実績!$A$5:$A$64,"Central Chidlom",実績!$B$5:$B$64,"VFF Scramkey",実績!$C$5:$C$64,"W"))/INDEX(設定!$B$12:$B$16,MATCH("Central Chidlom",設定!$A$12:$A$16,0)) -> 1.75 | J6: =(SUMIFS(実績!$D$5:$D$64,実績!$A$5:$A$64,"Siam Discovery",実績!$B$5:$B$64,"VFF Trailope",実績!$C$5:$C$64,"M")+SUMIFS(実績!$D$5:$D$64,実績!$A$5:$A$64,"Siam Discovery",実績!$B$5:$B$64,"VFF Trailope",実績!$C$5:$C$64,"W")+SUMIFS(実績!$D$5:$D$64,実績!$A$5:$A$64,"Siam Discovery",実績!$B$5:$B$64,"VFF Scramkey",実績!$C$5:$C$64,"M")+SUMIFS(実績!$D$5:$D$64,実績!$A$5:$A$64,"Siam Discovery",実績!$B$5:$B$64,"VFF Scramkey",実績!$C$5:$C$64,"W"))/INDEX(設定!$B$12:$B$16,MATCH("Siam Discovery",設定!$A$12:$A$16,0)) -> 1.75 | K6: =(SUMIFS(実績!$D$5:$D$64,実績!$A$5:$A$64,"Paradise Park",実績!$B$5:$B$64,"VFF Trailope",実績!$C$5:$C$64,"M")+SUMIFS(実績!$D$5:$D$64,実績!$A$5:$A$64,"Paradise Park",実績!$B$5:$B$64,"VFF Trailope",実績!$C$5:$C$64,"W")+SUMIFS(実績!$D$5:$D$64,実績!$A$5:$A$64,"Paradise Park",実績!$B$5:$B$64,"VFF Scramkey",実績!$C$5:$C$64,"M")+SUMIFS(実績!$D$5:$D$64,実績!$A$5:$A$64,"Paradise Park",実績!$B$5:$B$64,"VFF Scramkey",実績!$C$5:$C$64,"W"))/INDEX(設定!$B$12:$B$16,MATCH("Paradise Park",設定!$A$12:$A$16,0)) -> 2.2 | L6: =(SUMIFS(実績!$D$5:$D$64,実績!$A$5:$A$64,"Central Lardprao (Dept.)",実績!$B$5:$B$64,"VFF Trailope",実績!$C$5:$C$64,"M")+SUMIFS(実績!$D$5:$D$64,実績!$A$5:$A$64,"Central Lardprao (Dept.)",実績!$B$5:$B$64,"VFF Trailope",実績!$C$5:$C$64,"W")+SUMIFS(実績!$D$5:$D$64,実績!$A$5:$A$64,"Central Lardprao (Dept.)",実績!$B$5:$B$64,"VFF Scramkey",実績!$C$5:$C$64,"M")+SUMIFS(実績!$D$5:$D$64,実績!$A$5:$A$64,"Central Lardprao (Dept.)",実績!$B$5:$B$64,"VFF Scramkey",実績!$C$5:$C$64,"W"))/INDEX(設定!$B$12:$B$16,MATCH("Central Lardprao (Dept.)",設定!$A$12:$A$16,0)) -> 0.25 | M6: =SUM(H6:L6) -> 9.45 | N6: =IF($M6=0,0,H6/$M6) -> 0.37037037 | O6: =IF($M6=0,0,I6/$M6) -> 0.18518519 | P6: =IF($M6=0,0,J6/$M6) -> 0.18518519 | Q6: =IF($M6=0,0,K6/$M6) -> 0.23280423 | R6: =IF($M6=0,0,L6/$M6) -> 0.026455026 | S6: =N6*INDEX(設定!$B$29:$B$33,1)+O6*INDEX(設定!$B$29:$B$33,2)+P6*INDEX(設定!$B$29:$B$33,3)+Q6*INDEX(設定!$B$29:$B$33,4)+R6*INDEX(設定!$B$29:$B$33,5) -> 1.015873
A7: K Village | B7: VFF Trailope | C7: M | D7: 18 | F7: GLS_M | G7: Groundsplay + Graspifier + Kso Evo（M） | H7: =(SUMIFS(実績!$D$5:$D$64,実績!$A$5:$A$64,"K Village",実績!$B$5:$B$64,"VFF Groundsplay",実績!$C$5:$C$64,"M")+SUMIFS(実績!$D$5:$D$64,実績!$A$5:$A$64,"K Village",実績!$B$5:$B$64,"VFF Graspifier",実績!$C$5:$C$64,"M")+SUMIFS(実績!$D$5:$D$64,実績!$A$5:$A$64,"K Village",実績!$B$5:$B$64,"VFF Kso Evo",実績!$C$5:$C$64,"M"))/INDEX(設定!$B$12:$B$16,MATCH("K Village",設定!$A$12:$A$16,0)) -> 14.375 | I7: =(SUMIFS(実績!$D$5:$D$64,実績!$A$5:$A$64,"Central Chidlom",実績!$B$5:$B$64,"VFF Groundsplay",実績!$C$5:$C$64,"M")+SUMIFS(実績!$D$5:$D$64,実績!$A$5:$A$64,"Central Chidlom",実績!$B$5:$B$64,"VFF Graspifier",実績!$C$5:$C$64,"M")+SUMIFS(実績!$D$5:$D$64,実績!$A$5:$A$64,"Central Chidlom",実績!$B$5:$B$64,"VFF Kso Evo",実績!$C$5:$C$64,"M"))/INDEX(設定!$B$12:$B$16,MATCH("Central Chidlom",設定!$A$12:$A$16,0)) -> 5 | J7: =(SUMIFS(実績!$D$5:$D$64,実績!$A$5:$A$64,"Siam Discovery",実績!$B$5:$B$64,"VFF Groundsplay",実績!$C$5:$C$64,"M")+SUMIFS(実績!$D$5:$D$64,実績!$A$5:$A$64,"Siam Discovery",実績!$B$5:$B$64,"VFF Graspifier",実績!$C$5:$C$64,"M")+SUMIFS(実績!$D$5:$D$64,実績!$A$5:$A$64,"Siam Discovery",実績!$B$5:$B$64,"VFF Kso Evo",実績!$C$5:$C$64,"M"))/INDEX(設定!$B$12:$B$16,MATCH("Siam Discovery",設定!$A$12:$A$16,0)) -> 4.25 | K7: =(SUMIFS(実績!$D$5:$D$64,実績!$A$5:$A$64,"Paradise Park",実績!$B$5:$B$64,"VFF Groundsplay",実績!$C$5:$C$64,"M")+SUMIFS(実績!$D$5:$D$64,実績!$A$5:$A$64,"Paradise Park",実績!$B$5:$B$64,"VFF Graspifier",実績!$C$5:$C$64,"M")+SUMIFS(実績!$D$5:$D$64,実績!$A$5:$A$64,"Paradise Park",実績!$B$5:$B$64,"VFF Kso Evo",実績!$C$5:$C$64,"M"))/INDEX(設定!$B$12:$B$16,MATCH("Paradise Park",設定!$A$12:$A$16,0)) -> 4.8 | L7: =(SUMIFS(実績!$D$5:$D$64,実績!$A$5:$A$64,"Central Lardprao (Dept.)",実績!$B$5:$B$64,"VFF Groundsplay",実績!$C$5:$C$64,"M")+SUMIFS(実績!$D$5:$D$64,実績!$A$5:$A$64,"Central Lardprao (Dept.)",実績!$B$5:$B$64,"VFF Graspifier",実績!$C$5:$C$64,"M")+SUMIFS(実績!$D$5:$D$64,実績!$A$5:$A$64,"Central Lardprao (Dept.)",実績!$B$5:$B$64,"VFF Kso Evo",実績!$C$5:$C$64,"M"))/INDEX(設定!$B$12:$B$16,MATCH("Central Lardprao (Dept.)",設定!$A$12:$A$16,0)) -> 0.75 | M7: =SUM(H7:L7) -> 29.175 | N7: =IF($M7=0,0,H7/$M7) -> 0.49271637 | O7: =IF($M7=0,0,I7/$M7) -> 0.17137961 | P7: =IF($M7=0,0,J7/$M7) -> 0.14567266 | Q7: =IF($M7=0,0,K7/$M7) -> 0.16452442 | R7: =IF($M7=0,0,L7/$M7) -> 0.025706941 | S7: =N7*INDEX(設定!$B$29:$B$33,1)+O7*INDEX(設定!$B$29:$B$33,2)+P7*INDEX(設定!$B$29:$B$33,3)+Q7*INDEX(設定!$B$29:$B$33,4)+R7*INDEX(設定!$B$29:$B$33,5) -> 1.0154242
A8: K Village | B8: VFF Trailope | C8: W | D8: 0 | F8: GLS_W | G8: Groundsplay + Graspifier + Kso Evo（W） | H8: =(SUMIFS(実績!$D$5:$D$64,実績!$A$5:$A$64,"K Village",実績!$B$5:$B$64,"VFF Groundsplay",実績!$C$5:$C$64,"W")+SUMIFS(実績!$D$5:$D$64,実績!$A$5:$A$64,"K Village",実績!$B$5:$B$64,"VFF Graspifier",実績!$C$5:$C$64,"W")+SUMIFS(実績!$D$5:$D$64,実績!$A$5:$A$64,"K Village",実績!$B$5:$B$64,"VFF Kso Evo",実績!$C$5:$C$64,"W"))/INDEX(設定!$B$12:$B$16,MATCH("K Village",設定!$A$12:$A$16,0)) -> 5.25 | I8: =(SUMIFS(実績!$D$5:$D$64,実績!$A$5:$A$64,"Central Chidlom",実績!$B$5:$B$64,"VFF Groundsplay",実績!$C$5:$C$64,"W")+SUMIFS(実績!$D$5:$D$64,実績!$A$5:$A$64,"Central Chidlom",実績!$B$5:$B$64,"VFF Graspifier",実績!$C$5:$C$64,"W")+SUMIFS(実績!$D$5:$D$64,実績!$A$5:$A$64,"Central Chidlom",実績!$B$5:$B$64,"VFF Kso Evo",実績!$C$5:$C$64,"W"))/INDEX(設定!$B$12:$B$16,MATCH("Central Chidlom",設定!$A$12:$A$16,0)) -> 2.125 | J8: =(SUMIFS(実績!$D$5:$D$64,実績!$A$5:$A$64,"Siam Discovery",実績!$B$5:$B$64,"VFF Groundsplay",実績!$C$5:$C$64,"W")+SUMIFS(実績!$D$5:$D$64,実績!$A$5:$A$64,"Siam Discovery",実績!$B$5:$B$64,"VFF Graspifier",実績!$C$5:$C$64,"W")+SUMIFS(実績!$D$5:$D$64,実績!$A$5:$A$64,"Siam Discovery",実績!$B$5:$B$64,"VFF Kso Evo",実績!$C$5:$C$64,"W"))/INDEX(設定!$B$12:$B$16,MATCH("Siam Discovery",設定!$A$12:$A$16,0)) -> 1.375 | K8: =(SUMIFS(実績!$D$5:$D$64,実績!$A$5:$A$64,"Paradise Park",実績!$B$5:$B$64,"VFF Groundsplay",実績!$C$5:$C$64,"W")+SUMIFS(実績!$D$5:$D$64,実績!$A$5:$A$64,"Paradise Park",実績!$B$5:$B$64,"VFF Graspifier",実績!$C$5:$C$64,"W")+SUMIFS(実績!$D$5:$D$64,実績!$A$5:$A$64,"Paradise Park",実績!$B$5:$B$64,"VFF Kso Evo",実績!$C$5:$C$64,"W"))/INDEX(設定!$B$12:$B$16,MATCH("Paradise Park",設定!$A$12:$A$16,0)) -> 1.6 | L8: =(SUMIFS(実績!$D$5:$D$64,実績!$A$5:$A$64,"Central Lardprao (Dept.)",実績!$B$5:$B$64,"VFF Groundsplay",実績!$C$5:$C$64,"W")+SUMIFS(実績!$D$5:$D$64,実績!$A$5:$A$64,"Central Lardprao (Dept.)",実績!$B$5:$B$64,"VFF Graspifier",実績!$C$5:$C$64,"W")+SUMIFS(実績!$D$5:$D$64,実績!$A$5:$A$64,"Central Lardprao (Dept.)",実績!$B$5:$B$64,"VFF Kso Evo",実績!$C$5:$C$64,"W"))/INDEX(設定!$B$12:$B$16,MATCH("Central Lardprao (Dept.)",設定!$A$12:$A$16,0)) -> 0 | M8: =SUM(H8:L8) -> 10.35 | N8: =IF($M8=0,0,H8/$M8) -> 0.50724638 | O8: =IF($M8=0,0,I8/$M8) -> 0.20531401 | P8: =IF($M8=0,0,J8/$M8) -> 0.13285024 | Q8: =IF($M8=0,0,K8/$M8) -> 0.15458937 | R8: =IF($M8=0,0,L8/$M8) -> 0 | S8: =N8*INDEX(設定!$B$29:$B$33,1)+O8*INDEX(設定!$B$29:$B$33,2)+P8*INDEX(設定!$B$29:$B$33,3)+Q8*INDEX(設定!$B$29:$B$33,4)+R8*INDEX(設定!$B$29:$B$33,5) -> 1
A9: K Village | B9: VFF Scramkey | C9: M | D9: 9
A10: K Village | B10: VFF Scramkey | C10: W | D10: 1
A11: K Village | B11: VFF Groundsplay | C11: M | D11: 10 | F11: （参考）店舗別 参考6モデル合計足数と月平均
A12: K Village | B12: VFF Groundsplay | C12: W | D12: 0 | F12: 店舗 | G12: 合計足数 | H12: 月数 | I12: 月平均
A13: K Village | B13: VFF Graspifier | C13: M | D13: 21 | F13: K Village | G13: =SUMIFS(実績!$D$5:$D$64,実績!$A$5:$A$64,"K Village") -> 225 | H13: =INDEX(設定!$B$12:$B$16,MATCH("K Village",設定!$A$12:$A$16,0)) -> 8 | I13: =G13/H13 -> 28.125
A14: K Village | B14: VFF Graspifier | C14: W | D14: 12 | F14: Central CL (Chidlom) | G14: =SUMIFS(実績!$D$5:$D$64,実績!$A$5:$A$64,"Central Chidlom") -> 97 | H14: =INDEX(設定!$B$12:$B$16,MATCH("Central Chidlom",設定!$A$12:$A$16,0)) -> 8 | I14: =G14/H14 -> 12.125
A15: K Village | B15: VFF Kso Evo | C15: M | D15: 84 | F15: Siam Discovery | G15: =SUMIFS(実績!$D$5:$D$64,実績!$A$5:$A$64,"Siam Discovery") -> 77 | H15: =INDEX(設定!$B$12:$B$16,MATCH("Siam Discovery",設定!$A$12:$A$16,0)) -> 8 | I15: =G15/H15 -> 9.625
A16: K Village | B16: VFF Kso Evo | C16: W | D16: 30 | F16: Paradise Park | G16: =SUMIFS(実績!$D$5:$D$64,実績!$A$5:$A$64,"Paradise Park") -> 47 | H16: =INDEX(設定!$B$12:$B$16,MATCH("Paradise Park",設定!$A$12:$A$16,0)) -> 5 | I16: =G16/H16 -> 9.4
A17: Central Chidlom | B17: VFF Spidrwalk | C17: M | D17: 19 | F17: Central LP (Lardprao) | G17: =SUMIFS(実績!$D$5:$D$64,実績!$A$5:$A$64,"Central Lardprao (Dept.)") -> 12 | H17: =INDEX(設定!$B$12:$B$16,MATCH("Central Lardprao (Dept.)",設定!$A$12:$A$16,0)) -> 8 | I17: =G17/H17 -> 1.5
A18: Central Chidlom | B18: VFF Spidrwalk | C18: W | D18: 7
A19: Central Chidlom | B19: VFF Trailope | C19: M | D19: 12
A20: Central Chidlom | B20: VFF Trailope | C20: W | D20: 0
A21: Central Chidlom | B21: VFF Scramkey | C21: M | D21: 1
A22: Central Chidlom | B22: VFF Scramkey | C22: W | D22: 1
A23: Central Chidlom | B23: VFF Groundsplay | C23: M | D23: 1
A24: Central Chidlom | B24: VFF Groundsplay | C24: W | D24: 0
A25: Central Chidlom | B25: VFF Graspifier | C25: M | D25: 15
A26: Central Chidlom | B26: VFF Graspifier | C26: W | D26: 9
A27: Central Chidlom | B27: VFF Kso Evo | C27: M | D27: 24
A28: Central Chidlom | B28: VFF Kso Evo | C28: W | D28: 8
A29: Siam Discovery | B29: VFF Spidrwalk | C29: M | D29: 14
... A64: Central Lardprao (Dept.) | B64: VFF Kso Evo | C64: W | D64: 0

Sheet 配分表
A1: 新入荷商品 店舗別配分表
A2: 店舗配分 = MIN( 1SKU上限 , MAX( 最低配分 , ROUND( 入荷数×投入率 × 正規化シェア(店舗シェア×調整係数) ) ) ) ＋ 手動調整（S〜W列）。上限で頭打ちになった分はOffice保留に回る。倉庫保留 = 入荷数 − 店舗合計。
S3: 手動調整（±足）：数式の結果に加減する例外分。空欄＝調整なし
A4: モデル | B4: カラー | C4: サイズ | D4: 性別 | E4: サイズ区分 | F4: 入荷数 | G4: 初回投入率 | H4: 初回投入数 | I4: 配分グループ | J4: K Village | K4: Central CL (Chidlom) | L4: Siam Discovery | M4: Paradise Park | N4: Central LP (Lardprao) | O4: 店舗合計 | P4: 倉庫保留 | Q4: チェック | S4: 調整 K Village | T4: 調整 Central CL | U4: 調整 Siam Discovery | V4: 調整 Paradise Park | W4: 調整 Central LP
A5: VFF Spidrwalk | B5: Brown/Black | C5: M40 | D5: =LEFT(C5,1) -> M | E5: 端 | F5: 9 | G5: =INDEX(設定!$B$6:$B$8,MATCH(A5,設定!$A$6:$A$8,0)) -> 0.26 | H5: =ROUND(F5*G5,0) -> 2 | I5: =IF(A5="VFF Spidrwalk","Spidrwalk",IF(A5="VFF Trailope WP","TrailopeWP","GLS_"&D5)) -> Spidrwalk | J5: =MIN(INDEX(設定!$E$20:$E$24,MATCH("K Village",設定!$A$20:$A$24,0)),MAX(INDEX(設定!$B$20:$D$24,MATCH("K Village",設定!$A$20:$A$24,0),MATCH($E5,設定!$B$19:$D$19,0)),ROUND($H5*INDEX(実績!$N$5:$R$8,MATCH($I5,実績!$F$5:$F$8,0),1)*INDEX(設定!$B$29:$B$33,MATCH("K Village",設定!$A$29:$A$33,0))/INDEX(実績!$S$5:$S$8,MATCH($I5,実績!$F$5:$F$8,0))/設定!$B$36,0)*設定!$B$36))+S5 -> 1 | K5: =MIN(INDEX(設定!$E$20:$E$24,MATCH("Central Chidlom",設定!$A$20:$A$24,0)),MAX(INDEX(設定!$B$20:$D$24,MATCH("Central Chidlom",設定!$A$20:$A$24,0),MATCH($E5,設定!$B$19:$D$19,0)),ROUND($H5*INDEX(実績!$N$5:$R$8,MATCH($I5,実績!$F$5:$F$8,0),2)*INDEX(設定!$B$29:$B$33,MATCH("Central Chidlom",設定!$A$29:$A$33,0))/INDEX(実績!$S$5:$S$8,MATCH($I5,実績!$F$5:$F$8,0))/設定!$B$36,0)*設定!$B$36))+T5 -> 1 | L5: =MIN(INDEX(設定!$E$20:$E$24,MATCH("Siam Discovery",設定!$A$20:$A$24,0)),MAX(INDEX(設定!$B$20:$D$24,MATCH("Siam Discovery",設定!$A$20:$A$24,0),MATCH($E5,設定!$B$19:$D$19,0)),ROUND($H5*INDEX(実績!$N$5:$R$8,MATCH($I5,実績!$F$5:$F$8,0),3)*INDEX(設定!$B$29:$B$33,MATCH("Siam Discovery",設定!$A$29:$A$33,0))/INDEX(実績!$S$5:$S$8,MATCH($I5,実績!$F$5:$F$8,0))/設定!$B$36,0)*設定!$B$36))+U5 -> 1 | M5: =MIN(INDEX(設定!$E$20:$E$24,MATCH("Paradise Park",設定!$A$20:$A$24,0)),MAX(INDEX(設定!$B$20:$D$24,MATCH("Paradise Park",設定!$A$20:$A$24,0),MATCH($E5,設定!$B$19:$D$19,0)),ROUND($H5*INDEX(実績!$N$5:$R$8,MATCH($I5,実績!$F$5:$F$8,0),4)*INDEX(設定!$B$29:$B$33,MATCH("Paradise Park",設定!$A$29:$A$33,0))/INDEX(実績!$S$5:$S$8,MATCH($I5,実績!$F$5:$F$8,0))/設定!$B$36,0)*設定!$B$36))+V5 -> 1 | N5: =MIN(INDEX(設定!$E$20:$E$24,MATCH("Central Lardprao (Dept.)",設定!$A$20:$A$24,0)),MAX(INDEX(設定!$B$20:$D$24,MATCH("Central Lardprao (Dept.)",設定!$A$20:$A$24,0),MATCH($E5,設定!$B$19:$D$19,0)),ROUND($H5*INDEX(実績!$N$5:$R$8,MATCH($I5,実績!$F$5:$F$8,0),5)*INDEX(設定!$B$29:$B$33,MATCH("Central Lardprao (Dept.)",設定!$A$29:$A$33,0))/INDEX(実績!$S$5:$S$8,MATCH($I5,実績!$F$5:$F$8,0))/設定!$B$36,0)*設定!$B$36))+W5 -> 0 | O5: =SUM(J5:N5) -> 4 | P5: =F5-O5 -> 5 | Q5: =IF(P5<0,"入荷数超過→要調整","") | V5: 1
A6: VFF Spidrwalk | B6: Brown/Black | C6: M41 | D6: =LEFT(C6,1) -> M | E6: 主要 | F6: 12 | G6: =INDEX(設定!$B$6:$B$8,MATCH(A6,設定!$A$6:$A$8,0)) -> 0.26 | H6: =ROUND(F6*G6,0) -> 3 | I6: =IF(A6="VFF Spidrwalk","Spidrwalk",IF(A6="VFF Trailope WP","TrailopeWP","GLS_"&D6)) -> Spidrwalk | J6: =MIN(INDEX(設定!$E$20:$E$24,MATCH("K Village",設定!$A$20:$A$24,0)),MAX(INDEX(設定!$B$20:$D$24,MATCH("K Village",設定!$A$20:$A$24,0),MATCH($E6,設定!$B$19:$D$19,0)),ROUND($H6*INDEX(実績!$N$5:$R$8,MATCH($I6,実績!$F$5:$F$8,0),1)*INDEX(設定!$B$29:$B$33,MATCH("K Village",設定!$A$29:$A$33,0))/INDEX(実績!$S$5:$S$8,MATCH($I6,実績!$F$5:$F$8,0))/設定!$B$36,0)*設定!$B$36))+S6 -> 2 | K6: =MIN(INDEX(設定!$E$20:$E$24,MATCH("Central Chidlom",設定!$A$20:$A$24,0)),MAX(INDEX(設定!$B$20:$D$24,MATCH("Central Chidlom",設定!$A$20:$A$24,0),MATCH($E6,設定!$B$19:$D$19,0)),ROUND($H6*INDEX(実績!$N$5:$R$8,MATCH($I6,実績!$F$5:$F$8,0),2)*INDEX(設定!$B$29:$B$33,MATCH("Central Chidlom",設定!$A$29:$A$33,0))/INDEX(実績!$S$5:$S$8,MATCH($I6,実績!$F$5:$F$8,0))/設定!$B$36,0)*設定!$B$36))+T6 -> 1 | L6: =MIN(INDEX(設定!$E$20:$E$24,MATCH("Siam Discovery",設定!$A$20:$A$24,0)),MAX(INDEX(設定!$B$20:$D$24,MATCH("Siam Discovery",設定!$A$20:$A$24,0),MATCH($E6,設定!$B$19:$D$19,0)),ROUND($H6*INDEX(実績!$N$5:$R$8,MATCH($I6,実績!$F$5:$F$8,0),3)*INDEX(設定!$B$29:$B$33,MATCH("Siam Discovery",設定!$A$29:$A$33,0))/INDEX(実績!$S$5:$S$8,MATCH($I6,実績!$F$5:$F$8,0))/設定!$B$36,0)*設定!$B$36))+U6 -> 1 | M6: =MIN(INDEX(設定!$E$20:$E$24,MATCH("Paradise Park",設定!$A$20:$A$24,0)),MAX(INDEX(設定!$B$20:$D$24,MATCH("Paradise Park",設定!$A$20:$A$24,0),MATCH($E6,設定!$B$19:$D$19,0)),ROUND($H6*INDEX(実績!$N$5:$R$8,MATCH($I6,実績!$F$5:$F$8,0),4)*INDEX(設定!$B$29:$B$33,MATCH("Paradise Park",設定!$A$29:$A$33,0))/INDEX(実績!$S$5:$S$8,MATCH($I6,実績!$F$5:$F$8,0))/設定!$B$36,0)*設定!$B$36))+V6 -> 1 | N6: =MIN(INDEX(設定!$E$20:$E$24,MATCH("Central Lardprao (Dept.)",設定!$A$20:$A$24,0)),MAX(INDEX(設定!$B$20:$D$24,MATCH("Central Lardprao (Dept.)",設定!$A$20:$A$24,0),MATCH($E6,設定!$B$19:$D$19,0)),ROUND($H6*INDEX(実績!$N$5:$R$8,MATCH($I6,実績!$F$5:$F$8,0),5)*INDEX(設定!$B$29:$B$33,MATCH("Central Lardprao (Dept.)",設定!$A$29:$A$33,0))/INDEX(実績!$S$5:$S$8,MATCH($I6,実績!$F$5:$F$8,0))/設定!$B$36,0)*設定!$B$36))+W6 -> 0 | O6: =SUM(J6:N6) -> 5 | P6: =F6-O6 -> 7 | Q6: =IF(P6<0,"入荷数超過→要調整","")
A7: VFF Spidrwalk | B7: Brown/Black | C7: M42 | D7: =LEFT(C7,1) -> M | E7: 主要 | F7: 21 | G7: =INDEX(設定!$B$6:$B$8,MATCH(A7,設定!$A$6:$A$8,0)) -> 0.26 | H7: =ROUND(F7*G7,0) -> 5 | I7: =IF(A7="VFF Spidrwalk","Spidrwalk",IF(A7="VFF Trailope WP","TrailopeWP","GLS_"&D7)) -> Spidrwalk | J7: =MIN(INDEX(設定!$E$20:$E$24,MATCH("K Village",設定!$A$20:$A$24,0)),MAX(INDEX(設定!$B$20:$D$24,MATCH("K Village",設定!$A$20:$A$24,0),MATCH($E7,設定!$B$19:$D$19,0)),ROUND($H7*INDEX(実績!$N$5:$R$8,MATCH($I7,実績!$F$5:$F$8,0),1)*INDEX(設定!$B$29:$B$33,MATCH("K Village",設定!$A$29:$A$33,0))/INDEX(実績!$S$5:$S$8,MATCH($I7,実績!$F$5:$F$8,0))/設定!$B$36,0)*設定!$B$36))+S7 -> 2 | K7: =MIN(INDEX(設定!$E$20:$E$24,MATCH("Central Chidlom",設定!$A$20:$A$24,0)),MAX(INDEX(設定!$B$20:$D$24,MATCH("Central Chidlom",設定!$A$20:$A$24,0),MATCH($E7,設定!$B$19:$D$19,0)),ROUND($H7*INDEX(実績!$N$5:$R$8,MATCH($I7,実績!$F$5:$F$8,0),2)*INDEX(設定!$B$29:$B$33,MATCH("Central Chidlom",設定!$A$29:$A$33,0))/INDEX(実績!$S$5:$S$8,MATCH($I7,実績!$F$5:$F$8,0))/設定!$B$36,0)*設定!$B$36))+T7 -> 1 | L7: =MIN(INDEX(設定!$E$20:$E$24,MATCH("Siam Discovery",設定!$A$20:$A$24,0)),MAX(INDEX(設定!$B$20:$D$24,MATCH("Siam Discovery",設定!$A$20:$A$24,0),MATCH($E7,設定!$B$19:$D$19,0)),ROUND($H7*INDEX(実績!$N$5:$R$8,MATCH($I7,実績!$F$5:$F$8,0),3)*INDEX(設定!$B$29:$B$33,MATCH("Siam Discovery",設定!$A$29:$A$33,0))/INDEX(実績!$S$5:$S$8,MATCH($I7,実績!$F$5:$F$8,0))/設定!$B$36,0)*設定!$B$36))+U7 -> 1 | M7: =MIN(INDEX(設定!$E$20:$E$24,MATCH("Paradise Park",設定!$A$20:$A$24,0)),MAX(INDEX(設定!$B$20:$D$24,MATCH("Paradise Park",設定!$A$20:$A$24,0),MATCH($E7,設定!$B$19:$D$19,0)),ROUND($H7*INDEX(実績!$N$5:$R$8,MATCH($I7,実績!$F$5:$F$8,0),4)*INDEX(設定!$B$29:$B$33,MATCH("Paradise Park",設定!$A$29:$A$33,0))/INDEX(実績!$S$5:$S$8,MATCH($I7,実績!$F$5:$F$8,0))/設定!$B$36,0)*設定!$B$36))+V7 -> 1 | N7: =MIN(INDEX(設定!$E$20:$E$24,MATCH("Central Lardprao (Dept.)",設定!$A$20:$A$24,0)),MAX(INDEX(設定!$B$20:$D$24,MATCH("Central Lardprao (Dept.)",設定!$A$20:$A$24,0),MATCH($E7,設定!$B$19:$D$19,0)),ROUND($H7*INDEX(実績!$N$5:$R$8,MATCH($I7,実績!$F$5:$F$8,0),5)*INDEX(設定!$B$29:$B$33,MATCH("Central Lardprao (Dept.)",設定!$A$29:$A$33,0))/INDEX(実績!$S$5:$S$8,MATCH($I7,実績!$F$5:$F$8,0))/設定!$B$36,0)*設定!$B$36))+W7 -> 0 | O7: =SUM(J7:N7) -> 5 | P7: =F7-O7 -> 16 | Q7: =IF(P7<0,"入荷数超過→要調整","")
A8: VFF Spidrwalk | B8: Brown/Black | C8: M43 | D8: =LEFT(C8,1) -> M | E8: 主要 | F8: 24 | G8: =INDEX(設定!$B$6:$B$8,MATCH(A8,設定!$A$6:$A$8,0)) -> 0.26 | H8: =ROUND(F8*G8,0) -> 6 | I8: =IF(A8="VFF Spidrwalk","Spidrwalk",IF(A8="VFF Trailope WP","TrailopeWP","GLS_"&D8)) -> Spidrwalk | J8: =MIN(INDEX(設定!$E$20:$E$24,MATCH("K Village",設定!$A$20:$A$24,0)),MAX(INDEX(設定!$B$20:$D$24,MATCH("K Village",設定!$A$20:$A$24,0),MATCH($E8,設定!$B$19:$D$19,0)),ROUND($H8*INDEX(実績!$N$5:$R$8,MATCH($I8,実績!$F$5:$F$8,0),1)*INDEX(設定!$B$29:$B$33,MATCH("K Village",設定!$A$29:$A$33,0))/INDEX(実績!$S$5:$S$8,MATCH($I8,実績!$F$5:$F$8,0))/設定!$B$36,0)*設定!$B$36))+S8 -> 2 | K8: =MIN(INDEX(設定!$E$20:$E$24,MATCH("Central Chidlom",設定!$A$20:$A$24,0)),MAX(INDEX(設定!$B$20:$D$24,MATCH("Central Chidlom",設定!$A$20:$A$24,0),MATCH($E8,設定!$B$19:$D$19,0)),ROUND($H8*INDEX(実績!$N$5:$R$8,MATCH($I8,実績!$F$5:$F$8,0),2)*INDEX(設定!$B$29:$B$33,MATCH("Central Chidlom",設定!$A$29:$A$33,0))/INDEX(実績!$S$5:$S$8,MATCH($I8,実績!$F$5:$F$8,0))/設定!$B$36,0)*設定!$B$36))+T8 -> 2 | L8: =MIN(INDEX(設定!$E$20:$E$24,MATCH("Siam Discovery",設定!$A$20:$A$24,0)),MAX(INDEX(設定!$B$20:$D$24,MATCH("Siam Discovery",設定!$A$20:$A$24,0),MATCH($E8,設定!$B$19:$D$19,0)),ROUND($H8*INDEX(実績!$N$5:$R$8,MATCH($I8,実績!$F$5:$F$8,0),3)*INDEX(設定!$B$29:$B$33,MATCH("Siam Discovery",設定!$A$29:$A$33,0))/INDEX(実績!$S$5:$S$8,MATCH($I8,実績!$F$5:$F$8,0))/設定!$B$36,0)*設定!$B$36))+U8 -> 1 | M8: =MIN(INDEX(設定!$E$20:$E$24,MATCH("Paradise Park",設定!$A$20:$A$24,0)),MAX(INDEX(設定!$B$20:$D$24,MATCH("Paradise Park",設定!$A$20:$A$24,0),MATCH($E8,設定!$B$19:$D$19,0)),ROUND($H8*INDEX(実績!$N$5:$R$8,MATCH($I8,実績!$F$5:$F$8,0),4)*INDEX(設定!$B$29:$B$33,MATCH("Paradise Park",設定!$A$29:$A$33,0))/INDEX(実績!$S$5:$S$8,MATCH($I8,実績!$F$5:$F$8,0))/設定!$B$36,0)*設定!$B$36))+V8 -> 1 | N8: =MIN(INDEX(設定!$E$20:$E$24,MATCH("Central Lardprao (Dept.)",設定!$A$20:$A$24,0)),MAX(INDEX(設定!$B$20:$D$24,MATCH("Central Lardprao (Dept.)",設定!$A$20:$A$24,0),MATCH($E8,設定!$B$19:$D$19,0)),ROUND($H8*INDEX(実績!$N$5:$R$8,MATCH($I8,実績!$F$5:$F$8,0),5)*INDEX(設定!$B$29:$B$33,MATCH("Central Lardprao (Dept.)",設定!$A$29:$A$33,0))/INDEX(実績!$S$5:$S$8,MATCH($I8,実績!$F$5:$F$8,0))/設定!$B$36,0)*設定!$B$36))+W8 -> 0 | O8: =SUM(J8:N8) -> 6 | P8: =F8-O8 -> 18 | Q8: =IF(P8<0,"入荷数超過→要調整","")
A9: VFF Spidrwalk | B9: Brown/Black | C9: M44 | D9: =LEFT(C9,1) -> M | E9: 主要 | F9: 15 | G9: =INDEX(設定!$B$6:$B$8,MATCH(A9,設定!$A$6:$A$8,0)) -> 0.26 | H9: =ROUND(F9*G9,0) -> 4 | I9: =IF(A9="VFF Spidrwalk","Spidrwalk",IF(A9="VFF Trailope WP","TrailopeWP","GLS_"&D9)) -> Spidrwalk | J9: =MIN(INDEX(設定!$E$20:$E$24,MATCH("K Village",設定!$A$20:$A$24,0)),MAX(INDEX(設定!$B$20:$D$24,MATCH("K Village",設定!$A$20:$A$24,0),MATCH($E9,設定!$B$19:$D$19,0)),ROUND($H9*INDEX(実績!$N$5:$R$8,MATCH($I9,実績!$F$5:$F$8,0),1)*INDEX(設定!$B$29:$B$33,MATCH("K Village",設定!$A$29:$A$33,0))/INDEX(実績!$S$5:$S$8,MATCH($I9,実績!$F$5:$F$8,0))/設定!$B$36,0)*設定!$B$36))+S9 -> 2 | K9: =MIN(INDEX(設定!$E$20:$E$24,MATCH("Central Chidlom",設定!$A$20:$A$24,0)),MAX(INDEX(設定!$B$20:$D$24,MATCH("Central Chidlom",設定!$A$20:$A$24,0),MATCH($E9,設定!$B$19:$D$19,0)),ROUND($H9*INDEX(実績!$N$5:$R$8,MATCH($I9,実績!$F$5:$F$8,0),2)*INDEX(設定!$B$29:$B$33,MATCH("Central Chidlom",設定!$A$29:$A$33,0))/INDEX(実績!$S$5:$S$8,MATCH($I9,実績!$F$5:$F$8,0))/設定!$B$36,0)*設定!$B$36))+T9 -> 1 | L9: =MIN(INDEX(設定!$E$20:$E$24,MATCH("Siam Discovery",設定!$A$20:$A$24,0)),MAX(INDEX(設定!$B$20:$D$24,MATCH("Siam Discovery",設定!$A$20:$A$24,0),MATCH($E9,設定!$B$19:$D$19,0)),ROUND($H9*INDEX(実績!$N$5:$R$8,MATCH($I9,実績!$F$5:$F$8,0),3)*INDEX(設定!$B$29:$B$33,MATCH("Siam Discovery",設定!$A$29:$A$33,0))/INDEX(実績!$S$5:$S$8,MATCH($I9,実績!$F$5:$F$8,0))/設定!$B$36,0)*設定!$B$36))+U9 -> 1 | M9: =MIN(INDEX(設定!$E$20:$E$24,MATCH("Paradise Park",設定!$A$20:$A$24,0)),MAX(INDEX(設定!$B$20:$D$24,MATCH("Paradise Park",設定!$A$20:$A$24,0),MATCH($E9,設定!$B$19:$D$19,0)),ROUND($H9*INDEX(実績!$N$5:$R$8,MATCH($I9,実績!$F$5:$F$8,0),4)*INDEX(設定!$B$29:$B$33,MATCH("Paradise Park",設定!$A$29:$A$33,0))/INDEX(実績!$S$5:$S$8,MATCH($I9,実績!$F$5:$F$8,0))/設定!$B$36,0)*設定!$B$36))+V9 -> 1 | N9: =MIN(INDEX(設定!$E$20:$E$24,MATCH("Central Lardprao (Dept.)",設定!$A$20:$A$24,0)),MAX(INDEX(設定!$B$20:$D$24,MATCH("Central Lardprao (Dept.)",設定!$A$20:$A$24,0),MATCH($E9,設定!$B$19:$D$19,0)),ROUND($H9*INDEX(実績!$N$5:$R$8,MATCH($I9,実績!$F$5:$F$8,0),5)*INDEX(設定!$B$29:$B$33,MATCH("Central Lardprao (Dept.)",設定!$A$29:$A$33,0))/INDEX(実績!$S$5:$S$8,MATCH($I9,実績!$F$5:$F$8,0))/設定!$B$36,0)*設定!$B$36))+W9 -> 0 | O9: =SUM(J9:N9) -> 5 | P9: =F9-O9 -> 10 | Q9: =IF(P9<0,"入荷数超過→要調整","")
A10: VFF Spidrwalk | B10: Brown/Black | C10: M45 | D10: =LEFT(C10,1) -> M | E10: 端 | F10: 12 | G10: =INDEX(設定!$B$6:$B$8,MATCH(A10,設定!$A$6:$A$8,0)) -> 0.26 | H10: =ROUND(F10*G10,0) -> 3 | I10: =IF(A10="VFF Spidrwalk","Spidrwalk",IF(A10="VFF Trailope WP","TrailopeWP","GLS_"&D10)) -> Spidrwalk | J10: =MIN(INDEX(設定!$E$20:$E$24,MATCH("K Village",設定!$A$20:$A$24,0)),MAX(INDEX(設定!$B$20:$D$24,MATCH("K Village",設定!$A$20:$A$24,0),MATCH($E10,設定!$B$19:$D$19,0)),ROUND($H10*INDEX(実績!$N$5:$R$8,MATCH($I10,実績!$F$5:$F$8,0),1)*INDEX(設定!$B$29:$B$33,MATCH("K Village",設定!$A$29:$A$33,0))/INDEX(実績!$S$5:$S$8,MATCH($I10,実績!$F$5:$F$8,0))/設定!$B$36,0)*設定!$B$36))+S10 -> 1 | K10: =MIN(INDEX(設定!$E$20:$E$24,MATCH("Central Chidlom",設定!$A$20:$A$24,0)),MAX(INDEX(設定!$B$20:$D$24,MATCH("Central Chidlom",設定!$A$20:$A$24,0),MATCH($E10,設定!$B$19:$D$19,0)),ROUND($H10*INDEX(実績!$N$5:$R$8,MATCH($I10,実績!$F$5:$F$8,0),2)*INDEX(設定!$B$29:$B$33,MATCH("Central Chidlom",設定!$A$29:$A$33,0))/INDEX(実績!$S$5:$S$8,MATCH($I10,実績!$F$5:$F$8,0))/設定!$B$36,0)*設定!$B$36))+T10 -> 1 | L10: =MIN(INDEX(設定!$E$20:$E$24,MATCH("Siam Discovery",設定!$A$20:$A$24,0)),MAX(INDEX(設定!$B$20:$D$24,MATCH("Siam Discovery",設定!$A$20:$A$24,0),MATCH($E10,設定!$B$19:$D$19,0)),ROUND($H10*INDEX(実績!$N$5:$R$8,MATCH($I10,実績!$F$5:$F$8,0),3)*INDEX(設定!$B$29:$B$33,MATCH("Siam Discovery",設定!$A$29:$A$33,0))/INDEX(実績!$S$5:$S$8,MATCH($I10,実績!$F$5:$F$8,0))/設定!$B$36,0)*設定!$B$36))+U10 -> 1 | M10: =MIN(INDEX(設定!$E$20:$E$24,MATCH("Paradise Park",設定!$A$20:$A$24,0)),MAX(INDEX(設定!$B$20:$D$24,MATCH("Paradise Park",設定!$A$20:$A$24,0),MATCH($E10,設定!$B$19:$D$19,0)),ROUND($H10*INDEX(実績!$N$5:$R$8,MATCH($I10,実績!$F$5:$F$8,0),4)*INDEX(設定!$B$29:$B$33,MATCH("Paradise Park",設定!$A$29:$A$33,0))/INDEX(実績!$S$5:$S$8,MATCH($I10,実績!$F$5:$F$8,0))/設定!$B$36,0)*設定!$B$36))+V10 -> 0 | N10: =MIN(INDEX(設定!$E$20:$E$24,MATCH("Central Lardprao (Dept.)",設定!$A$20:$A$24,0)),MAX(INDEX(設定!$B$20:$D$24,MATCH("Central Lardprao (Dept.)",設定!$A$20:$A$24,0),MATCH($E10,設定!$B$19:$D$19,0)),ROUND($H10*INDEX(実績!$N$5:$R$8,MATCH($I10,実績!$F$5:$F$8,0),5)*INDEX(設定!$B$29:$B$33,MATCH("Central Lardprao (Dept.)",設定!$A$29:$A$33,0))/INDEX(実績!$S$5:$S$8,MATCH($I10,実績!$F$5:$F$8,0))/設定!$B$36,0)*設定!$B$36))+W10 -> 0 | O10: =SUM(J10:N10) -> 3 | P10: =F10-O10 -> 9 | Q10: =IF(P10<0,"入荷数超過→要調整","")
A11: VFF Spidrwalk | B11: Brown/Black | C11: M46 | D11: =LEFT(C11,1) -> M | E11: 端 | F11: 9 | G11: =INDEX(設定!$B$6:$B$8,MATCH(A11,設定!$A$6:$A$8,0)) -> 0.26 | H11: =ROUND(F11*G11,0) -> 2 | I11: =IF(A11="VFF Spidrwalk","Spidrwalk",IF(A11="VFF Trailope WP","TrailopeWP","GLS_"&D11)) -> Spidrwalk | J11: =MIN(INDEX(設定!$E$20:$E$24,MATCH("K Village",設定!$A$20:$A$24,0)),MAX(INDEX(設定!$B$20:$D$24,MATCH("K Village",設定!$A$20:$A$24,0),MATCH($E11,設定!$B$19:$D$19,0)),ROUND($H11*INDEX(実績!$N$5:$R$8,MATCH($I11,実績!$F$5:$F$8,0),1)*INDEX(設定!$B$29:$B$33,MATCH("K Village",設定!$A$29:$A$33,0))/INDEX(実績!$S$5:$S$8,MATCH($I11,実績!$F$5:$F$8,0))/設定!$B$36,0)*設定!$B$36))+S11 -> 1 | K11: =MIN(INDEX(設定!$E$20:$E$24,MATCH("Central Chidlom",設定!$A$20:$A$24,0)),MAX(INDEX(設定!$B$20:$D$24,MATCH("Central Chidlom",設定!$A$20:$A$24,0),MATCH($E11,設定!$B$19:$D$19,0)),ROUND($H11*INDEX(実績!$N$5:$R$8,MATCH($I11,実績!$F$5:$F$8,0),2)*INDEX(設定!$B$29:$B$33,MATCH("Central Chidlom",設定!$A$29:$A$33,0))/INDEX(実績!$S$5:$S$8,MATCH($I11,実績!$F$5:$F$8,0))/設定!$B$36,0)*設定!$B$36))+T11 -> 1 | L11: =MIN(INDEX(設定!$E$20:$E$24,MATCH("Siam Discovery",設定!$A$20:$A$24,0)),MAX(INDEX(設定!$B$20:$D$24,MATCH("Siam Discovery",設定!$A$20:$A$24,0),MATCH($E11,設定!$B$19:$D$19,0)),ROUND($H11*INDEX(実績!$N$5:$R$8,MATCH($I11,実績!$F$5:$F$8,0),3)*INDEX(設定!$B$29:$B$33,MATCH("Siam Discovery",設定!$A$29:$A$33,0))/INDEX(実績!$S$5:$S$8,MATCH($I11,実績!$F$5:$F$8,0))/設定!$B$36,0)*設定!$B$36))+U11 -> 1 | M11: =MIN(INDEX(設定!$E$20:$E$24,MATCH("Paradise Park",設定!$A$20:$A$24,0)),MAX(INDEX(設定!$B$20:$D$24,MATCH("Paradise Park",設定!$A$20:$A$24,0),MATCH($E11,設定!$B$19:$D$19,0)),ROUND($H11*INDEX(実績!$N$5:$R$8,MATCH($I11,実績!$F$5:$F$8,0),4)*INDEX(設定!$B$29:$B$33,MATCH("Paradise Park",設定!$A$29:$A$33,0))/INDEX(実績!$S$5:$S$8,MATCH($I11,実績!$F$5:$F$8,0))/設定!$B$36,0)*設定!$B$36))+V11 -> 0 | N11: =MIN(INDEX(設定!$E$20:$E$24,MATCH("Central Lardprao (Dept.)",設定!$A$20:$A$24,0)),MAX(INDEX(設定!$B$20:$D$24,MATCH("Central Lardprao (Dept.)",設定!$A$20:$A$24,0),MATCH($E11,設定!$B$19:$D$19,0)),ROUND($H11*INDEX(実績!$N$5:$R$8,MATCH($I11,実績!$F$5:$F$8,0),5)*INDEX(設定!$B$29:$B$33,MATCH("Central Lardprao (Dept.)",設定!$A$29:$A$33,0))/INDEX(実績!$S$5:$S$8,MATCH($I11,実績!$F$5:$F$8,0))/設定!$B$36,0)*設定!$B$36))+W11 -> 0 | O11: =SUM(J11:N11) -> 3 | P11: =F11-O11 -> 6 | Q11: =IF(P11<0,"入荷数超過→要調整","")
A12: VFF Spidrwalk | B12: Brown/Black | C12: M47 | D12: =LEFT(C12,1) -> M | E12: 極端 | F12: 6 | G12: =INDEX(設定!$B$6:$B$8,MATCH(A12,設定!$A$6:$A$8,0)) -> 0.26 | H12: =ROUND(F12*G12,0) -> 2 | I12: =IF(A12="VFF Spidrwalk","Spidrwalk",IF(A12="VFF Trailope WP","TrailopeWP","GLS_"&D12)) -> Spidrwalk | J12: =MIN(INDEX(設定!$E$20:$E$24,MATCH("K Village",設定!$A$20:$A$24,0)),MAX(INDEX(設定!$B$20:$D$24,MATCH("K Village",設定!$A$20:$A$24,0),MATCH($E12,設定!$B$19:$D$19,0)),ROUND($H12*INDEX(実績!$N$5:$R$8,MATCH($I12,実績!$F$5:$F$8,0),1)*INDEX(設定!$B$29:$B$33,MATCH("K Village",設定!$A$29:$A$33,0))/INDEX(実績!$S$5:$S$8,MATCH($I12,実績!$F$5:$F$8,0))/設定!$B$36,0)*設定!$B$36))+S12 -> 1 | K12: =MIN(INDEX(設定!$E$20:$E$24,MATCH("Central Chidlom",設定!$A$20:$A$24,0)),MAX(INDEX(設定!$B$20:$D$24,MATCH("Central Chidlom",設定!$A$20:$A$24,0),MATCH($E12,設定!$B$19:$D$19,0)),ROUND($H12*INDEX(実績!$N$5:$R$8,MATCH($I12,実績!$F$5:$F$8,0),2)*INDEX(設定!$B$29:$B$33,MATCH("Central Chidlom",設定!$A$29:$A$33,0))/INDEX(実績!$S$5:$S$8,MATCH($I12,実績!$F$5:$F$8,0))/設定!$B$36,0)*設定!$B$36))+T12 -> 1 | L12: =MIN(INDEX(設定!$E$20:$E$24,MATCH("Siam Discovery",設定!$A$20:$A$24,0)),MAX(INDEX(設定!$B$20:$D$24,MATCH("Siam Discovery",設定!$A$20:$A$24,0),MATCH($E12,設定!$B$19:$D$19,0)),ROUND($H12*INDEX(実績!$N$5:$R$8,MATCH($I12,実績!$F$5:$F$8,0),3)*INDEX(設定!$B$29:$B$33,MATCH("Siam Discovery",設定!$A$29:$A$33,0))/INDEX(実績!$S$5:$S$8,MATCH($I12,実績!$F$5:$F$8,0))/設定!$B$36,0)*設定!$B$36))+U12 -> 0 | M12: =MIN(INDEX(設定!$E$20:$E$24,MATCH("Paradise Park",設定!$A$20:$A$24,0)),MAX(INDEX(設定!$B$20:$D$24,MATCH("Paradise Park",設定!$A$20:$A$24,0),MATCH($E12,設定!$B$19:$D$19,0)),ROUND($H12*INDEX(実績!$N$5:$R$8,MATCH($I12,実績!$F$5:$F$8,0),4)*INDEX(設定!$B$29:$B$33,MATCH("Paradise Park",設定!$A$29:$A$33,0))/INDEX(実績!$S$5:$S$8,MATCH($I12,実績!$F$5:$F$8,0))/設定!$B$36,0)*設定!$B$36))+V12 -> 0 | N12: =MIN(INDEX(設定!$E$20:$E$24,MATCH("Central Lardprao (Dept.)",設定!$A$20:$A$24,0)),MAX(INDEX(設定!$B$20:$D$24,MATCH("Central Lardprao (Dept.)",設定!$A$20:$A$24,0),MATCH($E12,設定!$B$19:$D$19,0)),ROUND($H12*INDEX(実績!$N$5:$R$8,MATCH($I12,実績!$F$5:$F$8,0),5)*INDEX(設定!$B$29:$B$33,MATCH("Central Lardprao (Dept.)",設定!$A$29:$A$33,0))/INDEX(実績!$S$5:$S$8,MATCH($I12,実績!$F$5:$F$8,0))/設定!$B$36,0)*設定!$B$36))+W12 -> 0 | O12: =SUM(J12:N12) -> 2 | P12: =F12-O12 -> 4 | Q12: =IF(P12<0,"入荷数超過→要調整","")
A13: VFF Trailope WP | B13: Brown/Black | C13: M39 | D13: =LEFT(C13,1) -> M | E13: 極端 | F13: 3 | G13: =INDEX(設定!$B$6:$B$8,MATCH(A13,設定!$A$6:$A$8,0)) -> 0.28 | H13: =ROUND(F13*G13,0) -> 1 | I13: =IF(A13="VFF Spidrwalk","Spidrwalk",IF(A13="VFF Trailope WP","TrailopeWP","GLS_"&D13)) -> TrailopeWP | J13: =MIN(INDEX(設定!$E$20:$E$24,MATCH("K Village",設定!$A$20:$A$24,0)),MAX(INDEX(設定!$B$20:$D$24,MATCH("K Village",設定!$A$20:$A$24,0),MATCH($E13,設定!$B$19:$D$19,0)),ROUND($H13*INDEX(実績!$N$5:$R$8,MATCH($I13,実績!$F$5:$F$8,0),1)*INDEX(設定!$B$29:$B$33,MATCH("K Village",設定!$A$29:$A$33,0))/INDEX(実績!$S$5:$S$8,MATCH($I13,実績!$F$5:$F$8,0))/設定!$B$36,0)*設定!$B$36))+S13 -> 1 | K13: =MIN(INDEX(設定!$E$20:$E$24,MATCH("Central Chidlom",設定!$A$20:$A$24,0)),MAX(INDEX(設定!$B$20:$D$24,MATCH("Central Chidlom",設定!$A$20:$A$24,0),MATCH($E13,設定!$B$19:$D$19,0)),ROUND($H13*INDEX(実績!$N$5:$R$8,MATCH($I13,実績!$F$5:$F$8,0),2)*INDEX(設定!$B$29:$B$33,MATCH("Central Chidlom",設定!$A$29:$A$33,0))/INDEX(実績!$S$5:$S$8,MATCH($I13,実績!$F$5:$F$8,0))/設定!$B$36,0)*設定!$B$36))+T13 -> 0 | L13: =MIN(INDEX(設定!$E$20:$E$24,MATCH("Siam Discovery",設定!$A$20:$A$24,0)),MAX(INDEX(設定!$B$20:$D$24,MATCH("Siam Discovery",設定!$A$20:$A$24,0),MATCH($E13,設定!$B$19:$D$19,0)),ROUND($H13*INDEX(実績!$N$5:$R$8,MATCH($I13,実績!$F$5:$F$8,0),3)*INDEX(設定!$B$29:$B$33,MATCH("Siam Discovery",設定!$A$29:$A$33,0))/INDEX(実績!$S$5:$S$8,MATCH($I13,実績!$F$5:$F$8,0))/設定!$B$36,0)*設定!$B$36))+U13 -> 0 | M13: =MIN(INDEX(設定!$E$20:$E$24,MATCH("Paradise Park",設定!$A$20:$A$24,0)),MAX(INDEX(設定!$B$20:$D$24,MATCH("Paradise Park",設定!$A$20:$A$24,0),MATCH($E13,設定!$B$19:$D$19,0)),ROUND($H13*INDEX(実績!$N$5:$R$8,MATCH($I13,実績!$F$5:$F$8,0),4)*INDEX(設定!$B$29:$B$33,MATCH("Paradise Park",設定!$A$29:$A$33,0))/INDEX(実績!$S$5:$S$8,MATCH($I13,実績!$F$5:$F$8,0))/設定!$B$36,0)*設定!$B$36))+V13 -> 0 | N13: =MIN(INDEX(設定!$E$20:$E$24,MATCH("Central Lardprao (Dept.)",設定!$A$20:$A$24,0)),MAX(INDEX(設定!$B$20:$D$24,MATCH("Central Lardprao (Dept.)",設定!$A$20:$A$24,0),MATCH($E13,設定!$B$19:$D$19,0)),ROUND($H13*INDEX(実績!$N$5:$R$8,MATCH($I13,実績!$F$5:$F$8,0),5)*INDEX(設定!$B$29:$B$33,MATCH("Central Lardprao (Dept.)",設定!$A$29:$A$33,0))/INDEX(実績!$S$5:$S$8,MATCH($I13,実績!$F$5:$F$8,0))/設定!$B$36,0)*設定!$B$36))+W13 -> 0 | O13: =SUM(J13:N13) -> 1 | P13: =F13-O13 -> 2 | Q13: =IF(P13<0,"入荷数超過→要調整","")
A14: VFF Trailope WP | B14: Brown/Black | C14: M40 | D14: =LEFT(C14,1) -> M | E14: 端 | F14: 9 | G14: =INDEX(設定!$B$6:$B$8,MATCH(A14,設定!$A$6:$A$8,0)) -> 0.28 | H14: =ROUND(F14*G14,0) -> 3 | I14: =IF(A14="VFF Spidrwalk","Spidrwalk",IF(A14="VFF Trailope WP","TrailopeWP","GLS_"&D14)) -> TrailopeWP | J14: =MIN(INDEX(設定!$E$20:$E$24,MATCH("K Village",設定!$A$20:$A$24,0)),MAX(INDEX(設定!$B$20:$D$24,MATCH("K Village",設定!$A$20:$A$24,0),MATCH($E14,設定!$B$19:$D$19,0)),ROUND($H14*INDEX(実績!$N$5:$R$8,MATCH($I14,実績!$F$5:$F$8,0),1)*INDEX(設定!$B$29:$B$33,MATCH("K Village",設定!$A$29:$A$33,0))/INDEX(実績!$S$5:$S$8,MATCH($I14,実績!$F$5:$F$8,0))/設定!$B$36,0)*設定!$B$36))+S14 -> 1 | K14: =MIN(INDEX(設定!$E$20:$E$24,MATCH("Central Chidlom",設定!$A$20:$A$24,0)),MAX(INDEX(設定!$B$20:$D$24,MATCH("Central Chidlom",設定!$A$20:$A$24,0),MATCH($E14,設定!$B$19:$D$19,0)),ROUND($H14*INDEX(実績!$N$5:$R$8,MATCH($I14,実績!$F$5:$F$8,0),2)*INDEX(設定!$B$29:$B$33,MATCH("Central Chidlom",設定!$A$29:$A$33,0))/INDEX(実績!$S$5:$S$8,MATCH($I14,実績!$F$5:$F$8,0))/設定!$B$36,0)*設定!$B$36))+T14 -> 1 | L14: =MIN(INDEX(設定!$E$20:$E$24,MATCH("Siam Discovery",設定!$A$20:$A$24,0)),MAX(INDEX(設定!$B$20:$D$24,MATCH("Siam Discovery",設定!$A$20:$A$24,0),MATCH($E14,設定!$B$19:$D$19,0)),ROUND($H14*INDEX(実績!$N$5:$R$8,MATCH($I14,実績!$F$5:$F$8,0),3)*INDEX(設定!$B$29:$B$33,MATCH("Siam Discovery",設定!$A$29:$A$33,0))/INDEX(実績!$S$5:$S$8,MATCH($I14,実績!$F$5:$F$8,0))/設定!$B$36,0)*設定!$B$36))+U14 -> 1 | M14: =MIN(INDEX(設定!$E$20:$E$24,MATCH("Paradise Park",設定!$A$20:$A$24,0)),MAX(INDEX(設定!$B$20:$D$24,MATCH("Paradise Park",設定!$A$20:$A$24,0),MATCH($E14,設定!$B$19:$D$19,0)),ROUND($H14*INDEX(実績!$N$5:$R$8,MATCH($I14,実績!$F$5:$F$8,0),4)*INDEX(設定!$B$29:$B$33,MATCH("Paradise Park",設定!$A$29:$A$33,0))/INDEX(実績!$S$5:$S$8,MATCH($I14,実績!$F$5:$F$8,0))/設定!$B$36,0)*設定!$B$36))+V14 -> 1 | N14: =MIN(INDEX(設定!$E$20:$E$24,MATCH("Central Lardprao (Dept.)",設定!$A$20:$A$24,0)),MAX(INDEX(設定!$B$20:$D$24,MATCH("Central Lardprao (Dept.)",設定!$A$20:$A$24,0),MATCH($E14,設定!$B$19:$D$19,0)),ROUND($H14*INDEX(実績!$N$5:$R$8,MATCH($I14,実績!$F$5:$F$8,0),5)*INDEX(設定!$B$29:$B$33,MATCH("Central Lardprao (Dept.)",設定!$A$29:$A$33,0))/INDEX(実績!$S$5:$S$8,MATCH($I14,実績!$F$5:$F$8,0))/設定!$B$36,0)*設定!$B$36))+W14 -> 0 | O14: =SUM(J14:N14) -> 4 | P14: =F14-O14 -> 5 | Q14: =IF(P14<0,"入荷数超過→要調整","")
A15: VFF Trailope WP | B15: Brown/Black | C15: M41 | D15: =LEFT(C15,1) -> M | E15: 主要 | F15: 18 | G15: =INDEX(設定!$B$6:$B$8,MATCH(A15,設定!$A$6:$A$8,0)) -> 0.28 | H15: =ROUND(F15*G15,0) -> 5 | I15: =IF(A15="VFF Spidrwalk","Spidrwalk",IF(A15="VFF Trailope WP","TrailopeWP","GLS_"&D15)) -> TrailopeWP | J15: =MIN(INDEX(設定!$E$20:$E$24,MATCH("K Village",設定!$A$20:$A$24,0)),MAX(INDEX(設定!$B$20:$D$24,MATCH("K Village",設定!$A$20:$A$24,0),MATCH($E15,設定!$B$19:$D$19,0)),ROUND($H15*INDEX(実績!$N$5:$R$8,MATCH($I15,実績!$F$5:$F$8,0),1)*INDEX(設定!$B$29:$B$33,MATCH("K Village",設定!$A$29:$A$33,0))/INDEX(実績!$S$5:$S$8,MATCH($I15,実績!$F$5:$F$8,0))/設定!$B$36,0)*設定!$B$36))+S15 -> 2 | K15: =MIN(INDEX(設定!$E$20:$E$24,MATCH("Central Chidlom",設定!$A$20:$A$24,0)),MAX(INDEX(設定!$B$20:$D$24,MATCH("Central Chidlom",設定!$A$20:$A$24,0),MATCH($E15,設定!$B$19:$D$19,0)),ROUND($H15*INDEX(実績!$N$5:$R$8,MATCH($I15,実績!$F$5:$F$8,0),2)*INDEX(設定!$B$29:$B$33,MATCH("Central Chidlom",設定!$A$29:$A$33,0))/INDEX(実績!$S$5:$S$8,MATCH($I15,実績!$F$5:$F$8,0))/設定!$B$36,0)*設定!$B$36))+T15 -> 1 | L15: =MIN(INDEX(設定!$E$20:$E$24,MATCH("Siam Discovery",設定!$A$20:$A$24,0)),MAX(INDEX(設定!$B$20:$D$24,MATCH("Siam Discovery",設定!$A$20:$A$24,0),MATCH($E15,設定!$B$19:$D$19,0)),ROUND($H15*INDEX(実績!$N$5:$R$8,MATCH($I15,実績!$F$5:$F$8,0),3)*INDEX(設定!$B$29:$B$33,MATCH("Siam Discovery",設定!$A$29:$A$33,0))/INDEX(実績!$S$5:$S$8,MATCH($I15,実績!$F$5:$F$8,0))/設定!$B$36,0)*設定!$B$36))+U15 -> 1 | M15: =MIN(INDEX(設定!$E$20:$E$24,MATCH("Paradise Park",設定!$A$20:$A$24,0)),MAX(INDEX(設定!$B$20:$D$24,MATCH("Paradise Park",設定!$A$20:$A$24,0),MATCH($E15,設定!$B$19:$D$19,0)),ROUND($H15*INDEX(実績!$N$5:$R$8,MATCH($I15,実績!$F$5:$F$8,0),4)*INDEX(設定!$B$29:$B$33,MATCH("Paradise Park",設定!$A$29:$A$33,0))/INDEX(実績!$S$5:$S$8,MATCH($I15,実績!$F$5:$F$8,0))/設定!$B$36,0)*設定!$B$36))+V15 -> 1 | N15: =MIN(INDEX(設定!$E$20:$E$24,MATCH("Central Lardprao (Dept.)",設定!$A$20:$A$24,0)),MAX(INDEX(設定!$B$20:$D$24,MATCH("Central Lardprao (Dept.)",設定!$A$20:$A$24,0),MATCH($E15,設定!$B$19:$D$19,0)),ROUND($H15*INDEX(実績!$N$5:$R$8,MATCH($I15,実績!$F$5:$F$8,0),5)*INDEX(設定!$B$29:$B$33,MATCH("Central Lardprao (Dept.)",設定!$A$29:$A$33,0))/INDEX(実績!$S$5:$S$8,MATCH($I15,実績!$F$5:$F$8,0))/設定!$B$36,0)*設定!$B$36))+W15 -> 0 | O15: =SUM(J15:N15) -> 5 | P15: =F15-O15 -> 13 | Q15: =IF(P15<0,"入荷数超過→要調整","")
A16: VFF Trailope WP | B16: Brown/Black | C16: M42 | D16: =LEFT(C16,1) -> M | E16: 主要 | F16: 24 | G16: =INDEX(設定!$B$6:$B$8,MATCH(A16,設定!$A$6:$A$8,0)) -> 0.28 | H16: =ROUND(F16*G16,0) -> 7 | I16: =IF(A16="VFF Spidrwalk","Spidrwalk",IF(A16="VFF Trailope WP","TrailopeWP","GLS_"&D16)) -> TrailopeWP | J16: =MIN(INDEX(設定!$E$20:$E$24,MATCH("K Village",設定!$A$20:$A$24,0)),MAX(INDEX(設定!$B$20:$D$24,MATCH("K Village",設定!$A$20:$A$24,0),MATCH($E16,設定!$B$19:$D$19,0)),ROUND($H16*INDEX(実績!$N$5:$R$8,MATCH($I16,実績!$F$5:$F$8,0),1)*INDEX(設定!$B$29:$B$33,MATCH("K Village",設定!$A$29:$A$33,0))/INDEX(実績!$S$5:$S$8,MATCH($I16,実績!$F$5:$F$8,0))/設定!$B$36,0)*設定!$B$36))+S16 -> 2 | K16: =MIN(INDEX(設定!$E$20:$E$24,MATCH("Central Chidlom",設定!$A$20:$A$24,0)),MAX(INDEX(設定!$B$20:$D$24,MATCH("Central Chidlom",設定!$A$20:$A$24,0),MATCH($E16,設定!$B$19:$D$19,0)),ROUND($H16*INDEX(実績!$N$5:$R$8,MATCH($I16,実績!$F$5:$F$8,0),2)*INDEX(設定!$B$29:$B$33,MATCH("Central Chidlom",設定!$A$29:$A$33,0))/INDEX(実績!$S$5:$S$8,MATCH($I16,実績!$F$5:$F$8,0))/設定!$B$36,0)*設定!$B$36))+T16 -> 1 | L16: =MIN(INDEX(設定!$E$20:$E$24,MATCH("Siam Discovery",設定!$A$20:$A$24,0)),MAX(INDEX(設定!$B$20:$D$24,MATCH("Siam Discovery",設定!$A$20:$A$24,0),MATCH($E16,設定!$B$19:$D$19,0)),ROUND($H16*INDEX(実績!$N$5:$R$8,MATCH($I16,実績!$F$5:$F$8,0),3)*INDEX(設定!$B$29:$B$33,MATCH("Siam Discovery",設定!$A$29:$A$33,0))/INDEX(実績!$S$5:$S$8,MATCH($I16,実績!$F$5:$F$8,0))/設定!$B$36,0)*設定!$B$36))+U16 -> 1 | M16: =MIN(INDEX(設定!$E$20:$E$24,MATCH("Paradise Park",設定!$A$20:$A$24,0)),MAX(INDEX(設定!$B$20:$D$24,MATCH("Paradise Park",設定!$A$20:$A$24,0),MATCH($E16,設定!$B$19:$D$19,0)),ROUND($H16*INDEX(実績!$N$5:$R$8,MATCH($I16,実績!$F$5:$F$8,0),4)*INDEX(設定!$B$29:$B$33,MATCH("Paradise Park",設定!$A$29:$A$33,0))/INDEX(実績!$S$5:$S$8,MATCH($I16,実績!$F$5:$F$8,0))/設定!$B$36,0)*設定!$B$36))+V16 -> 2 | N16: =MIN(INDEX(設定!$E$20:$E$24,MATCH("Central Lardprao (Dept.)",設定!$A$20:$A$24,0)),MAX(INDEX(設定!$B$20:$D$24,MATCH("Central Lardprao (Dept.)",設定!$A$20:$A$24,0),MATCH($E16,設定!$B$19:$D$19,0)),ROUND($H16*INDEX(実績!$N$5:$R$8,MATCH($I16,実績!$F$5:$F$8,0),5)*INDEX(設定!$B$29:$B$33,MATCH("Central Lardprao (Dept.)",設定!$A$29:$A$33,0))/INDEX(実績!$S$5:$S$8,MATCH($I16,実績!$F$5:$F$8,0))/設定!$B$36,0)*設定!$B$36))+W16 -> 1 | O16: =SUM(J16:N16) -> 7 | P16: =F16-O16 -> 17 | Q16: =IF(P16<0,"入荷数超過→要調整","") | W16: 1
A17: VFF Trailope WP | B17: Brown/Black | C17: M43 | D17: =LEFT(C17,1) -> M | E17: 主要 | F17: 30 | G17: =INDEX(設定!$B$6:$B$8,MATCH(A17,設定!$A$6:$A$8,0)) -> 0.28 | H17: =ROUND(F17*G17,0) -> 8 | I17: =IF(A17="VFF Spidrwalk","Spidrwalk",IF(A17="VFF Trailope WP","TrailopeWP","GLS_"&D17)) -> TrailopeWP | J17: =MIN(INDEX(設定!$E$20:$E$24,MATCH("K Village",設定!$A$20:$A$24,0)),MAX(INDEX(設定!$B$20:$D$24,MATCH("K Village",設定!$A$20:$A$24,0),MATCH($E17,設定!$B$19:$D$19,0)),ROUND($H17*INDEX(実績!$N$5:$R$8,MATCH($I17,実績!$F$5:$F$8,0),1)*INDEX(設定!$B$29:$B$33,MATCH("K Village",設定!$A$29:$A$33,0))/INDEX(実績!$S$5:$S$8,MATCH($I17,実績!$F$5:$F$8,0))/設定!$B$36,0)*設定!$B$36))+S17 -> 2 | K17: =MIN(INDEX(設定!$E$20:$E$24,MATCH("Central Chidlom",設定!$A$20:$A$24,0)),MAX(INDEX(設定!$B$20:$D$24,MATCH("Central Chidlom",設定!$A$20:$A$24,0),MATCH($E17,設定!$B$19:$D$19,0)),ROUND($H17*INDEX(実績!$N$5:$R$8,MATCH($I17,実績!$F$5:$F$8,0),2)*INDEX(設定!$B$29:$B$33,MATCH("Central Chidlom",設定!$A$29:$A$33,0))/INDEX(実績!$S$5:$S$8,MATCH($I17,実績!$F$5:$F$8,0))/設定!$B$36,0)*設定!$B$36))+T17 -> 1 | L17: =MIN(INDEX(設定!$E$20:$E$24,MATCH("Siam Discovery",設定!$A$20:$A$24,0)),MAX(INDEX(設定!$B$20:$D$24,MATCH("Siam Discovery",設定!$A$20:$A$24,0),MATCH($E17,設定!$B$19:$D$19,0)),ROUND($H17*INDEX(実績!$N$5:$R$8,MATCH($I17,実績!$F$5:$F$8,0),3)*INDEX(設定!$B$29:$B$33,MATCH("Siam Discovery",設定!$A$29:$A$33,0))/INDEX(実績!$S$5:$S$8,MATCH($I17,実績!$F$5:$F$8,0))/設定!$B$36,0)*設定!$B$36))+U17 -> 1 | M17: =MIN(INDEX(設定!$E$20:$E$24,MATCH("Paradise Park",設定!$A$20:$A$24,0)),MAX(INDEX(設定!$B$20:$D$24,MATCH("Paradise Park",設定!$A$20:$A$24,0),MATCH($E17,設定!$B$19:$D$19,0)),ROUND($H17*INDEX(実績!$N$5:$R$8,MATCH($I17,実績!$F$5:$F$8,0),4)*INDEX(設定!$B$29:$B$33,MATCH("Paradise Park",設定!$A$29:$A$33,0))/INDEX(実績!$S$5:$S$8,MATCH($I17,実績!$F$5:$F$8,0))/設定!$B$36,0)*設定!$B$36))+V17 -> 2 | N17: =MIN(INDEX(設定!$E$20:$E$24,MATCH("Central Lardprao (Dept.)",設定!$A$20:$A$24,0)),MAX(INDEX(設定!$B$20:$D$24,MATCH("Central Lardprao (Dept.)",設定!$A$20:$A$24,0),MATCH($E17,設定!$B$19:$D$19,0)),ROUND($H17*INDEX(実績!$N$5:$R$8,MATCH($I17,実績!$F$5:$F$8,0),5)*INDEX(設定!$B$29:$B$33,MATCH("Central Lardprao (Dept.)",設定!$A$29:$A$33,0))/INDEX(実績!$S$5:$S$8,MATCH($I17,実績!$F$5:$F$8,0))/設定!$B$36,0)*設定!$B$36))+W17 -> 1 | O17: =SUM(J17:N17) -> 7 | P17: =F17-O17 -> 23 | Q17: =IF(P17<0,"入荷数超過→要調整","") | W17: 1
A18: VFF Trailope WP | B18: Brown/Black | C18: M44 | D18: =LEFT(C18,1) -> M | E18: 主要 | F18: 21 | G18: =INDEX(設定!$B$6:$B$8,MATCH(A18,設定!$A$6:$A$8,0)) -> 0.28 | H18: =ROUND(F18*G18,0) -> 6 | I18: =IF(A18="VFF Spidrwalk","Spidrwalk",IF(A18="VFF Trailope WP","TrailopeWP","GLS_"&D18)) -> TrailopeWP | J18: =MIN(INDEX(設定!$E$20:$E$24,MATCH("K Village",設定!$A$20:$A$24,0)),MAX(INDEX(設定!$B$20:$D$24,MATCH("K Village",設定!$A$20:$A$24,0),MATCH($E18,設定!$B$19:$D$19,0)),ROUND($H18*INDEX(実績!$N$5:$R$8,MATCH($I18,実績!$F$5:$F$8,0),1)*INDEX(設定!$B$29:$B$33,MATCH("K Village",設定!$A$29:$A$33,0))/INDEX(実績!$S$5:$S$8,MATCH($I18,実績!$F$5:$F$8,0))/設定!$B$36,0)*設定!$B$36))+S18 -> 2 | K18: =MIN(INDEX(設定!$E$20:$E$24,MATCH("Central Chidlom",設定!$A$20:$A$24,0)),MAX(INDEX(設定!$B$20:$D$24,MATCH("Central Chidlom",設定!$A$20:$A$24,0),MATCH($E18,設定!$B$19:$D$19,0)),ROUND($H18*INDEX(実績!$N$5:$R$8,MATCH($I18,実績!$F$5:$F$8,0),2)*INDEX(設定!$B$29:$B$33,MATCH("Central Chidlom",設定!$A$29:$A$33,0))/INDEX(実績!$S$5:$S$8,MATCH($I18,実績!$F$5:$F$8,0))/設定!$B$36,0)*設定!$B$36))+T18 -> 1 | L18: =MIN(INDEX(設定!$E$20:$E$24,MATCH("Siam Discovery",設定!$A$20:$A$24,0)),MAX(INDEX(設定!$B$20:$D$24,MATCH("Siam Discovery",設定!$A$20:$A$24,0),MATCH($E18,設定!$B$19:$D$19,0)),ROUND($H18*INDEX(実績!$N$5:$R$8,MATCH($I18,実績!$F$5:$F$8,0),3)*INDEX(設定!$B$29:$B$33,MATCH("Siam Discovery",設定!$A$29:$A$33,0))/INDEX(実績!$S$5:$S$8,MATCH($I18,実績!$F$5:$F$8,0))/設定!$B$36,0)*設定!$B$36))+U18 -> 1 | M18: =MIN(INDEX(設定!$E$20:$E$24,MATCH("Paradise Park",設定!$A$20:$A$24,0)),MAX(INDEX(設定!$B$20:$D$24,MATCH("Paradise Park",設定!$A$20:$A$24,0),MATCH($E18,設定!$B$19:$D$19,0)),ROUND($H18*INDEX(実績!$N$5:$R$8,MATCH($I18,実績!$F$5:$F$8,0),4)*INDEX(設定!$B$29:$B$33,MATCH("Paradise Park",設定!$A$29:$A$33,0))/INDEX(実績!$S$5:$S$8,MATCH($I18,実績!$F$5:$F$8,0))/設定!$B$36,0)*設定!$B$36))+V18 -> 1 | N18: =MIN(INDEX(設定!$E$20:$E$24,MATCH("Central Lardprao (Dept.)",設定!$A$20:$A$24,0)),MAX(INDEX(設定!$B$20:$D$24,MATCH("Central Lardprao (Dept.)",設定!$A$20:$A$24,0),MATCH($E18,設定!$B$19:$D$19,0)),ROUND($H18*INDEX(実績!$N$5:$R$8,MATCH($I18,実績!$F$5:$F$8,0),5)*INDEX(設定!$B$29:$B$33,MATCH("Central Lardprao (Dept.)",設定!$A$29:$A$33,0))/INDEX(実績!$S$5:$S$8,MATCH($I18,実績!$F$5:$F$8,0))/設定!$B$36,0)*設定!$B$36))+W18 -> 0 | O18: =SUM(J18:N18) -> 5 | P18: =F18-O18 -> 16 | Q18: =IF(P18<0,"入荷数超過→要調整","")
A19: VFF Trailope WP | B19: Brown/Black | C19: M45 | D19: =LEFT(C19,1) -> M | E19: 端 | F19: 12 | G19: =INDEX(設定!$B$6:$B$8,MATCH(A19,設定!$A$6:$A$8,0)) -> 0.28 | H19: =ROUND(F19*G19,0) -> 3 | I19: =IF(A19="VFF Spidrwalk","Spidrwalk",IF(A19="VFF Trailope WP","TrailopeWP","GLS_"&D19)) -> TrailopeWP | J19: =MIN(INDEX(設定!$E$20:$E$24,MATCH("K Village",設定!$A$20:$A$24,0)),MAX(INDEX(設定!$B$20:$D$24,MATCH("K Village",設定!$A$20:$A$24,0),MATCH($E19,設定!$B$19:$D$19,0)),ROUND($H19*INDEX(実績!$N$5:$R$8,MATCH($I19,実績!$F$5:$F$8,0),1)*INDEX(設定!$B$29:$B$33,MATCH("K Village",設定!$A$29:$A$33,0))/INDEX(実績!$S$5:$S$8,MATCH($I19,実績!$F$5:$F$8,0))/設定!$B$36,0)*設定!$B$36))+S19 -> 1 | K19: =MIN(INDEX(設定!$E$20:$E$24,MATCH("Central Chidlom",設定!$A$20:$A$24,0)),MAX(INDEX(設定!$B$20:$D$24,MATCH("Central Chidlom",設定!$A$20:$A$24,0),MATCH($E19,設定!$B$19:$D$19,0)),ROUND($H19*INDEX(実績!$N$5:$R$8,MATCH($I19,実績!$F$5:$F$8,0),2)*INDEX(設定!$B$29:$B$33,MATCH("Central Chidlom",設定!$A$29:$A$33,0))/INDEX(実績!$S$5:$S$8,MATCH($I19,実績!$F$5:$F$8,0))/設定!$B$36,0)*設定!$B$36))+T19 -> 1 | L19: =MIN(INDEX(設定!$E$20:$E$24,MATCH("Siam Discovery",設定!$A$20:$A$24,0)),MAX(INDEX(設定!$B$20:$D$24,MATCH("Siam Discovery",設定!$A$20:$A$24,0),MATCH($E19,設定!$B$19:$D$19,0)),ROUND($H19*INDEX(実績!$N$5:$R$8,MATCH($I19,実績!$F$5:$F$8,0),3)*INDEX(設定!$B$29:$B$33,MATCH("Siam Discovery",設定!$A$29:$A$33,0))/INDEX(実績!$S$5:$S$8,MATCH($I19,実績!$F$5:$F$8,0))/設定!$B$36,0)*設定!$B$36))+U19 -> 1 | M19: =MIN(INDEX(設定!$E$20:$E$24,MATCH("Paradise Park",設定!$A$20:$A$24,0)),MAX(INDEX(設定!$B$20:$D$24,MATCH("Paradise Park",設定!$A$20:$A$24,0),MATCH($E19,設定!$B$19:$D$19,0)),ROUND($H19*INDEX(実績!$N$5:$R$8,MATCH($I19,実績!$F$5:$F$8,0),4)*INDEX(設定!$B$29:$B$33,MATCH("Paradise Park",設定!$A$29:$A$33,0))/INDEX(実績!$S$5:$S$8,MATCH($I19,実績!$F$5:$F$8,0))/設定!$B$36,0)*設定!$B$36))+V19 -> 1 | N19: =MIN(INDEX(設定!$E$20:$E$24,MATCH("Central Lardprao (Dept.)",設定!$A$20:$A$24,0)),MAX(INDEX(設定!$B$20:$D$24,MATCH("Central Lardprao (Dept.)",設定!$A$20:$A$24,0),MATCH($E19,設定!$B$19:$D$19,0)),ROUND($H19*INDEX(実績!$N$5:$R$8,MATCH($I19,実績!$F$5:$F$8,0),5)*INDEX(設定!$B$29:$B$33,MATCH("Central Lardprao (Dept.)",設定!$A$29:$A$33,0))/INDEX(実績!$S$5:$S$8,MATCH($I19,実績!$F$5:$F$8,0))/設定!$B$36,0)*設定!$B$36))+W19 -> 0 | O19: =SUM(J19:N19) -> 4 | P19: =F19-O19 -> 8 | Q19: =IF(P19<0,"入荷数超過→要調整","")
A20: VFF Trailope WP | B20: Brown/Black | C20: M46 | D20: =LEFT(C20,1) -> M | E20: 端 | F20: 9 | G20: =INDEX(設定!$B$6:$B$8,MATCH(A20,設定!$A$6:$A$8,0)) -> 0.28 | H20: =ROUND(F20*G20,0) -> 3 | I20: =IF(A20="VFF Spidrwalk","Spidrwalk",IF(A20="VFF Trailope WP","TrailopeWP","GLS_"&D20)) -> TrailopeWP | J20: =MIN(INDEX(設定!$E$20:$E$24,MATCH("K Village",設定!$A$20:$A$24,0)),MAX(INDEX(設定!$B$20:$D$24,MATCH("K Village",設定!$A$20:$A$24,0),MATCH($E20,設定!$B$19:$D$19,0)),ROUND($H20*INDEX(実績!$N$5:$R$8,MATCH($I20,実績!$F$5:$F$8,0),1)*INDEX(設定!$B$29:$B$33,MATCH("K Village",設定!$A$29:$A$33,0))/INDEX(実績!$S$5:$S$8,MATCH($I20,実績!$F$5:$F$8,0))/設定!$B$36,0)*設定!$B$36))+S20 -> 1 | K20: =MIN(INDEX(設定!$E$20:$E$24,MATCH("Central Chidlom",設定!$A$20:$A$24,0)),MAX(INDEX(設定!$B$20:$D$24,MATCH("Central Chidlom",設定!$A$20:$A$24,0),MATCH($E20,設定!$B$19:$D$19,0)),ROUND($H20*INDEX(実績!$N$5:$R$8,MATCH($I20,実績!$F$5:$F$8,0),2)*INDEX(設定!$B$29:$B$33,MATCH("Central Chidlom",設定!$A$29:$A$33,0))/INDEX(実績!$S$5:$S$8,MATCH($I20,実績!$F$5:$F$8,0))/設定!$B$36,0)*設定!$B$36))+T20 -> 1 | L20: =MIN(INDEX(設定!$E$20:$E$24,MATCH("Siam Discovery",設定!$A$20:$A$24,0)),MAX(INDEX(設定!$B$20:$D$24,MATCH("Siam Discovery",設定!$A$20:$A$24,0),MATCH($E20,設定!$B$19:$D$19,0)),ROUND($H20*INDEX(実績!$N$5:$R$8,MATCH($I20,実績!$F$5:$F$8,0),3)*INDEX(設定!$B$29:$B$33,MATCH("Siam Discovery",設定!$A$29:$A$33,0))/INDEX(実績!$S$5:$S$8,MATCH($I20,実績!$F$5:$F$8,0))/設定!$B$36,0)*設定!$B$36))+U20 -> 1 | M20: =MIN(INDEX(設定!$E$20:$E$24,MATCH("Paradise Park",設定!$A$20:$A$24,0)),MAX(INDEX(設定!$B$20:$D$24,MATCH("Paradise Park",設定!$A$20:$A$24,0),MATCH($E20,設定!$B$19:$D$19,0)),ROUND($H20*INDEX(実績!$N$5:$R$8,MATCH($I20,実績!$F$5:$F$8,0),4)*INDEX(設定!$B$29:$B$33,MATCH("Paradise Park",設定!$A$29:$A$33,0))/INDEX(実績!$S$5:$S$8,MATCH($I20,実績!$F$5:$F$8,0))/設定!$B$36,0)*設定!$B$36))+V20 -> 1 | N20: =MIN(INDEX(設定!$E$20:$E$24,MATCH("Central Lardprao (Dept.)",設定!$A$20:$A$24,0)),MAX(INDEX(設定!$B$20:$D$24,MATCH("Central Lardprao (Dept.)",設定!$A$20:$A$24,0),MATCH($E20,設定!$B$19:$D$19,0)),ROUND($H20*INDEX(実績!$N$5:$R$8,MATCH($I20,実績!$F$5:$F$8,0),5)*INDEX(設定!$B$29:$B$33,MATCH("Central Lardprao (Dept.)",設定!$A$29:$A$33,0))/INDEX(実績!$S$5:$S$8,MATCH($I20,実績!$F$5:$F$8,0))/設定!$B$36,0)*設定!$B$36))+W20 -> 0 | O20: =SUM(J20:N20) -> 4 | P20: =F20-O20 -> 5 | Q20: =IF(P20<0,"入荷数超過→要調整","")
A21: VFF Trailope WP | B21: Brown/Black | C21: M47 | D21: =LEFT(C21,1) -> M | E21: 極端 | F21: 6 | G21: =INDEX(設定!$B$6:$B$8,MATCH(A21,設定!$A$6:$A$8,0)) -> 0.28 | H21: =ROUND(F21*G21,0) -> 2 | I21: =IF(A21="VFF Spidrwalk","Spidrwalk",IF(A21="VFF Trailope WP","TrailopeWP","GLS_"&D21)) -> TrailopeWP | J21: =MIN(INDEX(設定!$E$20:$E$24,MATCH("K Village",設定!$A$20:$A$24,0)),MAX(INDEX(設定!$B$20:$D$24,MATCH("K Village",設定!$A$20:$A$24,0),MATCH($E21,設定!$B$19:$D$19,0)),ROUND($H21*INDEX(実績!$N$5:$R$8,MATCH($I21,実績!$F$5:$F$8,0),1)*INDEX(設定!$B$29:$B$33,MATCH("K Village",設定!$A$29:$A$33,0))/INDEX(実績!$S$5:$S$8,MATCH($I21,実績!$F$5:$F$8,0))/設定!$B$36,0)*設定!$B$36))+S21 -> 1 | K21: =MIN(INDEX(設定!$E$20:$E$24,MATCH("Central Chidlom",設定!$A$20:$A$24,0)),MAX(INDEX(設定!$B$20:$D$24,MATCH("Central Chidlom",設定!$A$20:$A$24,0),MATCH($E21,設定!$B$19:$D$19,0)),ROUND($H21*INDEX(実績!$N$5:$R$8,MATCH($I21,実績!$F$5:$F$8,0),2)*INDEX(設定!$B$29:$B$33,MATCH("Central Chidlom",設定!$A$29:$A$33,0))/INDEX(実績!$S$5:$S$8,MATCH($I21,実績!$F$5:$F$8,0))/設定!$B$36,0)*設定!$B$36))+T21 -> 0 | L21: =MIN(INDEX(設定!$E$20:$E$24,MATCH("Siam Discovery",設定!$A$20:$A$24,0)),MAX(INDEX(設定!$B$20:$D$24,MATCH("Siam Discovery",設定!$A$20:$A$24,0),MATCH($E21,設定!$B$19:$D$19,0)),ROUND($H21*INDEX(実績!$N$5:$R$8,MATCH($I21,実績!$F$5:$F$8,0),3)*INDEX(設定!$B$29:$B$33,MATCH("Siam Discovery",設定!$A$29:$A$33,0))/INDEX(実績!$S$5:$S$8,MATCH($I21,実績!$F$5:$F$8,0))/設定!$B$36,0)*設定!$B$36))+U21 -> 0 | M21: =MIN(INDEX(設定!$E$20:$E$24,MATCH("Paradise Park",設定!$A$20:$A$24,0)),MAX(INDEX(設定!$B$20:$D$24,MATCH("Paradise Park",設定!$A$20:$A$24,0),MATCH($E21,設定!$B$19:$D$19,0)),ROUND($H21*INDEX(実績!$N$5:$R$8,MATCH($I21,実績!$F$5:$F$8,0),4)*INDEX(設定!$B$29:$B$33,MATCH("Paradise Park",設定!$A$29:$A$33,0))/INDEX(実績!$S$5:$S$8,MATCH($I21,実績!$F$5:$F$8,0))/設定!$B$36,0)*設定!$B$36))+V21 -> 0 | N21: =MIN(INDEX(設定!$E$20:$E$24,MATCH("Central Lardprao (Dept.)",設定!$A$20:$A$24,0)),MAX(INDEX(設定!$B$20:$D$24,MATCH("Central Lardprao (Dept.)",設定!$A$20:$A$24,0),MATCH($E21,設定!$B$19:$D$19,0)),ROUND($H21*INDEX(実績!$N$5:$R$8,MATCH($I21,実績!$F$5:$F$8,0),5)*INDEX(設定!$B$29:$B$33,MATCH("Central Lardprao (Dept.)",設定!$A$29:$A$33,0))/INDEX(実績!$S$5:$S$8,MATCH($I21,実績!$F$5:$F$8,0))/設定!$B$36,0)*設定!$B$36))+W21 -> 0 | O21: =SUM(J21:N21) -> 1 | P21: =F21-O21 -> 5 | Q21: =IF(P21<0,"入荷数超過→要調整","")
A22: VFF Groundsplay LS | B22: Total Black | C22: M40 | D22: =LEFT(C22,1) -> M | E22: 端 | F22: 18 | G22: =INDEX(設定!$B$6:$B$8,MATCH(A22,設定!$A$6:$A$8,0)) -> 0.33 | H22: =ROUND(F22*G22,0) -> 6 | I22: =IF(A22="VFF Spidrwalk","Spidrwalk",IF(A22="VFF Trailope WP","TrailopeWP","GLS_"&D22)) -> GLS_M | J22: =MIN(INDEX(設定!$E$20:$E$24,MATCH("K Village",設定!$A$20:$A$24,0)),MAX(INDEX(設定!$B$20:$D$24,MATCH("K Village",設定!$A$20:$A$24,0),MATCH($E22,設定!$B$19:$D$19,0)),ROUND($H22*INDEX(実績!$N$5:$R$8,MATCH($I22,実績!$F$5:$F$8,0),1)*INDEX(設定!$B$29:$B$33,MATCH("K Village",設定!$A$29:$A$33,0))/INDEX(実績!$S$5:$S$8,MATCH($I22,実績!$F$5:$F$8,0))/設定!$B$36,0)*設定!$B$36))+S22 -> 2 | K22: =MIN(INDEX(設定!$E$20:$E$24,MATCH("Central Chidlom",設定!$A$20:$A$24,0)),MAX(INDEX(設定!$B$20:$D$24,MATCH("Central Chidlom",設定!$A$20:$A$24,0),MATCH($E22,設定!$B$19:$D$19,0)),ROUND($H22*INDEX(実績!$N$5:$R$8,MATCH($I22,実績!$F$5:$F$8,0),2)*INDEX(設定!$B$29:$B$33,MATCH("Central Chidlom",設定!$A$29:$A$33,0))/INDEX(実績!$S$5:$S$8,MATCH($I22,実績!$F$5:$F$8,0))/設定!$B$36,0)*設定!$B$36))+T22 -> 1 | L22: =MIN(INDEX(設定!$E$20:$E$24,MATCH("Siam Discovery",設定!$A$20:$A$24,0)),MAX(INDEX(設定!$B$20:$D$24,MATCH("Siam Discovery",設定!$A$20:$A$24,0),MATCH($E22,設定!$B$19:$D$19,0)),ROUND($H22*INDEX(実績!$N$5:$R$8,MATCH($I22,実績!$F$5:$F$8,0),3)*INDEX(設定!$B$29:$B$33,MATCH("Siam Discovery",設定!$A$29:$A$33,0))/INDEX(実績!$S$5:$S$8,MATCH($I22,実績!$F$5:$F$8,0))/設定!$B$36,0)*設定!$B$36))+U22 -> 1 | M22: =MIN(INDEX(設定!$E$20:$E$24,MATCH("Paradise Park",設定!$A$20:$A$24,0)),MAX(INDEX(設定!$B$20:$D$24,MATCH("Paradise Park",設定!$A$20:$A$24,0),MATCH($E22,設定!$B$19:$D$19,0)),ROUND($H22*INDEX(実績!$N$5:$R$8,MATCH($I22,実績!$F$5:$F$8,0),4)*INDEX(設定!$B$29:$B$33,MATCH("Paradise Park",設定!$A$29:$A$33,0))/INDEX(実績!$S$5:$S$8,MATCH($I22,実績!$F$5:$F$8,0))/設定!$B$36,0)*設定!$B$36))+V22 -> 1 | N22: =MIN(INDEX(設定!$E$20:$E$24,MATCH("Central Lardprao (Dept.)",設定!$A$20:$A$24,0)),MAX(INDEX(設定!$B$20:$D$24,MATCH("Central Lardprao (Dept.)",設定!$A$20:$A$24,0),MATCH($E22,設定!$B$19:$D$19,0)),ROUND($H22*INDEX(実績!$N$5:$R$8,MATCH($I22,実績!$F$5:$F$8,0),5)*INDEX(設定!$B$29:$B$33,MATCH("Central Lardprao (Dept.)",設定!$A$29:$A$33,0))/INDEX(実績!$S$5:$S$8,MATCH($I22,実績!$F$5:$F$8,0))/設定!$B$36,0)*設定!$B$36))+W22 -> 0 | O22: =SUM(J22:N22) -> 5 | P22: =F22-O22 -> 13 | Q22: =IF(P22<0,"入荷数超過→要調整","")
A23: VFF Groundsplay LS | B23: Total Black | C23: M41 | D23: =LEFT(C23,1) -> M | E23: 主要 | F23: 27 | G23: =INDEX(設定!$B$6:$B$8,MATCH(A23,設定!$A$6:$A$8,0)) -> 0.33 | H23: =ROUND(F23*G23,0) -> 9 | I23: =IF(A23="VFF Spidrwalk","Spidrwalk",IF(A23="VFF Trailope WP","TrailopeWP","GLS_"&D23)) -> GLS_M | J23: =MIN(INDEX(設定!$E$20:$E$24,MATCH("K Village",設定!$A$20:$A$24,0)),MAX(INDEX(設定!$B$20:$D$24,MATCH("K Village",設定!$A$20:$A$24,0),MATCH($E23,設定!$B$19:$D$19,0)),ROUND($H23*INDEX(実績!$N$5:$R$8,MATCH($I23,実績!$F$5:$F$8,0),1)*INDEX(設定!$B$29:$B$33,MATCH("K Village",設定!$A$29:$A$33,0))/INDEX(実績!$S$5:$S$8,MATCH($I23,実績!$F$5:$F$8,0))/設定!$B$36,0)*設定!$B$36))+S23 -> 2 | K23: =MIN(INDEX(設定!$E$20:$E$24,MATCH("Central Chidlom",設定!$A$20:$A$24,0)),MAX(INDEX(設定!$B$20:$D$24,MATCH("Central Chidlom",設定!$A$20:$A$24,0),MATCH($E23,設定!$B$19:$D$19,0)),ROUND($H23*INDEX(実績!$N$5:$R$8,MATCH($I23,実績!$F$5:$F$8,0),2)*INDEX(設定!$B$29:$B$33,MATCH("Central Chidlom",設定!$A$29:$A$33,0))/INDEX(実績!$S$5:$S$8,MATCH($I23,実績!$F$5:$F$8,0))/設定!$B$36,0)*設定!$B$36))+T23 -> 2 | L23: =MIN(INDEX(設定!$E$20:$E$24,MATCH("Siam Discovery",設定!$A$20:$A$24,0)),MAX(INDEX(設定!$B$20:$D$24,MATCH("Siam Discovery",設定!$A$20:$A$24,0),MATCH($E23,設定!$B$19:$D$19,0)),ROUND($H23*INDEX(実績!$N$5:$R$8,MATCH($I23,実績!$F$5:$F$8,0),3)*INDEX(設定!$B$29:$B$33,MATCH("Siam Discovery",設定!$A$29:$A$33,0))/INDEX(実績!$S$5:$S$8,MATCH($I23,実績!$F$5:$F$8,0))/設定!$B$36,0)*設定!$B$36))+U23 -> 1 | M23: =MIN(INDEX(設定!$E$20:$E$24,MATCH("Paradise Park",設定!$A$20:$A$24,0)),MAX(INDEX(設定!$B$20:$D$24,MATCH("Paradise Park",設定!$A$20:$A$24,0),MATCH($E23,設定!$B$19:$D$19,0)),ROUND($H23*INDEX(実績!$N$5:$R$8,MATCH($I23,実績!$F$5:$F$8,0),4)*INDEX(設定!$B$29:$B$33,MATCH("Paradise Park",設定!$A$29:$A$33,0))/INDEX(実績!$S$5:$S$8,MATCH($I23,実績!$F$5:$F$8,0))/設定!$B$36,0)*設定!$B$36))+V23 -> 1 | N23: =MIN(INDEX(設定!$E$20:$E$24,MATCH("Central Lardprao (Dept.)",設定!$A$20:$A$24,0)),MAX(INDEX(設定!$B$20:$D$24,MATCH("Central Lardprao (Dept.)",設定!$A$20:$A$24,0),MATCH($E23,設定!$B$19:$D$19,0)),ROUND($H23*INDEX(実績!$N$5:$R$8,MATCH($I23,実績!$F$5:$F$8,0),5)*INDEX(設定!$B$29:$B$33,MATCH("Central Lardprao (Dept.)",設定!$A$29:$A$33,0))/INDEX(実績!$S$5:$S$8,MATCH($I23,実績!$F$5:$F$8,0))/設定!$B$36,0)*設定!$B$36))+W23 -> 0 | O23: =SUM(J23:N23) -> 6 | P23: =F23-O23 -> 21 | Q23: =IF(P23<0,"入荷数超過→要調整","")
